2021-10-22 15:11:10,928 django.request WARNING  Not Found: /explore/2
2021-11-08 19:20:38,227 django.request ERROR    Internal Server Error: /login/
Traceback (most recent call last):
  File "C:\Users\tarlo\Desktop\Code\DJANGO\instamiligram\venv\lib\site-packages\django\core\handlers\exception.py", line 47, in inner
    response = get_response(request)
  File "C:\Users\tarlo\Desktop\Code\DJANGO\instamiligram\venv\lib\site-packages\django\core\handlers\base.py", line 181, in _get_response
    response = wrapped_callback(request, *callback_args, **callback_kwargs)
  File "C:\Users\tarlo\Desktop\Code\DJANGO\instamiligram\venv\lib\site-packages\django\views\generic\base.py", line 70, in view
    return self.dispatch(request, *args, **kwargs)
  File "C:\Users\tarlo\Desktop\Code\DJANGO\instamiligram\venv\lib\site-packages\django\views\generic\base.py", line 98, in dispatch
    return handler(request, *args, **kwargs)
  File "C:\Users\tarlo\Desktop\Code\DJANGO\instamiligram\users\views.py", line 37, in post
    login(request, user)
  File "C:\Users\tarlo\Desktop\Code\DJANGO\instamiligram\venv\lib\site-packages\django\contrib\auth\__init__.py", line 135, in login
    user_logged_in.send(sender=user.__class__, request=request, user=user)
  File "C:\Users\tarlo\Desktop\Code\DJANGO\instamiligram\venv\lib\site-packages\django\dispatch\dispatcher.py", line 180, in send
    return [
  File "C:\Users\tarlo\Desktop\Code\DJANGO\instamiligram\venv\lib\site-packages\django\dispatch\dispatcher.py", line 181, in <listcomp>
    (receiver, receiver(signal=self, sender=sender, **named))
  File "C:\Users\tarlo\Desktop\Code\DJANGO\instamiligram\venv\lib\site-packages\django\contrib\auth\models.py", line 22, in update_last_login
    user.save(update_fields=['last_login'])
  File "C:\Users\tarlo\Desktop\Code\DJANGO\instamiligram\venv\lib\site-packages\django\contrib\auth\base_user.py", line 67, in save
    super().save(*args, **kwargs)
  File "C:\Users\tarlo\Desktop\Code\DJANGO\instamiligram\venv\lib\site-packages\django\db\models\base.py", line 726, in save
    self.save_base(using=using, force_insert=force_insert,
  File "C:\Users\tarlo\Desktop\Code\DJANGO\instamiligram\venv\lib\site-packages\django\db\models\base.py", line 774, in save_base
    post_save.send(
  File "C:\Users\tarlo\Desktop\Code\DJANGO\instamiligram\venv\lib\site-packages\django\dispatch\dispatcher.py", line 180, in send
    return [
  File "C:\Users\tarlo\Desktop\Code\DJANGO\instamiligram\venv\lib\site-packages\django\dispatch\dispatcher.py", line 181, in <listcomp>
    (receiver, receiver(signal=self, sender=sender, **named))
  File "C:\Users\tarlo\Desktop\Code\DJANGO\instamiligram\users\signals.py", line 15, in save_profile
    instance.profile.save()
  File "C:\Users\tarlo\Desktop\Code\DJANGO\instamiligram\users\models.py", line 26, in save
    img = Image.open(self.image.path)
  File "C:\Users\tarlo\Desktop\Code\DJANGO\instamiligram\venv\lib\site-packages\PIL\Image.py", line 2975, in open
    fp = builtins.open(filename, "rb")
FileNotFoundError: [Errno 2] No such file or directory: 'C:\\Users\\tarlo\\Desktop\\Code\\DJANGO\\instamiligram\\media\\profile_pics\\650812.jpg'
2021-11-08 19:20:38,397 django.request WARNING  Not Found: /favicon.ico
2021-11-08 19:21:03,491 django.request ERROR    Internal Server Error: /login/
Traceback (most recent call last):
  File "C:\Users\tarlo\Desktop\Code\DJANGO\instamiligram\venv\lib\site-packages\django\core\handlers\exception.py", line 47, in inner
    response = get_response(request)
  File "C:\Users\tarlo\Desktop\Code\DJANGO\instamiligram\venv\lib\site-packages\django\core\handlers\base.py", line 181, in _get_response
    response = wrapped_callback(request, *callback_args, **callback_kwargs)
  File "C:\Users\tarlo\Desktop\Code\DJANGO\instamiligram\venv\lib\site-packages\django\views\generic\base.py", line 70, in view
    return self.dispatch(request, *args, **kwargs)
  File "C:\Users\tarlo\Desktop\Code\DJANGO\instamiligram\venv\lib\site-packages\django\views\generic\base.py", line 98, in dispatch
    return handler(request, *args, **kwargs)
  File "C:\Users\tarlo\Desktop\Code\DJANGO\instamiligram\users\views.py", line 37, in post
    login(request, user)
  File "C:\Users\tarlo\Desktop\Code\DJANGO\instamiligram\venv\lib\site-packages\django\contrib\auth\__init__.py", line 135, in login
    user_logged_in.send(sender=user.__class__, request=request, user=user)
  File "C:\Users\tarlo\Desktop\Code\DJANGO\instamiligram\venv\lib\site-packages\django\dispatch\dispatcher.py", line 180, in send
    return [
  File "C:\Users\tarlo\Desktop\Code\DJANGO\instamiligram\venv\lib\site-packages\django\dispatch\dispatcher.py", line 181, in <listcomp>
    (receiver, receiver(signal=self, sender=sender, **named))
  File "C:\Users\tarlo\Desktop\Code\DJANGO\instamiligram\venv\lib\site-packages\django\contrib\auth\models.py", line 22, in update_last_login
    user.save(update_fields=['last_login'])
  File "C:\Users\tarlo\Desktop\Code\DJANGO\instamiligram\venv\lib\site-packages\django\contrib\auth\base_user.py", line 67, in save
    super().save(*args, **kwargs)
  File "C:\Users\tarlo\Desktop\Code\DJANGO\instamiligram\venv\lib\site-packages\django\db\models\base.py", line 726, in save
    self.save_base(using=using, force_insert=force_insert,
  File "C:\Users\tarlo\Desktop\Code\DJANGO\instamiligram\venv\lib\site-packages\django\db\models\base.py", line 774, in save_base
    post_save.send(
  File "C:\Users\tarlo\Desktop\Code\DJANGO\instamiligram\venv\lib\site-packages\django\dispatch\dispatcher.py", line 180, in send
    return [
  File "C:\Users\tarlo\Desktop\Code\DJANGO\instamiligram\venv\lib\site-packages\django\dispatch\dispatcher.py", line 181, in <listcomp>
    (receiver, receiver(signal=self, sender=sender, **named))
  File "C:\Users\tarlo\Desktop\Code\DJANGO\instamiligram\users\signals.py", line 15, in save_profile
    instance.profile.save()
  File "C:\Users\tarlo\Desktop\Code\DJANGO\instamiligram\users\models.py", line 26, in save
    img = Image.open(self.image.path)
  File "C:\Users\tarlo\Desktop\Code\DJANGO\instamiligram\venv\lib\site-packages\PIL\Image.py", line 2975, in open
    fp = builtins.open(filename, "rb")
FileNotFoundError: [Errno 2] No such file or directory: 'C:\\Users\\tarlo\\Desktop\\Code\\DJANGO\\instamiligram\\media\\profile_pics\\650812.jpg'
2021-11-08 19:21:46,347 django.request WARNING  Not Found: /media/post_pics/1016619_ywWHyLs.jpg
2021-11-08 19:21:46,349 django.request WARNING  Not Found: /media/profile_pics/650812.jpg
2021-11-08 19:21:46,353 django.request WARNING  Not Found: /media/post_pics/Без_названия_sIJlGzm.jfif
2021-11-08 19:21:55,918 django.request WARNING  Not Found: /media/profile_pics/650812.jpg
2021-11-08 19:21:55,921 django.request WARNING  Not Found: /media/post_pics/1016619_ywWHyLs.jpg
2021-11-08 19:21:55,926 django.request WARNING  Not Found: /media/post_pics/Без_названия_sIJlGzm.jfif
2021-11-08 19:22:02,870 django.request WARNING  Not Found: /media/profile_pics/650812.jpg
2021-11-08 19:22:02,879 django.request WARNING  Not Found: /media/post_pics/1016619_ywWHyLs.jpg
2021-11-08 19:22:02,883 django.request WARNING  Not Found: /media/post_pics/Без_названия_sIJlGzm.jfif
2021-11-08 19:22:05,252 django.request WARNING  Not Found: /media/profile_pics/650812.jpg
2021-11-08 19:22:05,256 django.request WARNING  Not Found: /media/post_pics/1016619_ywWHyLs.jpg
2021-11-08 19:22:05,260 django.request WARNING  Not Found: /media/post_pics/Без_названия_sIJlGzm.jfif
2021-11-08 19:27:26,940 django.request WARNING  Not Found: /media/profile_pics/650812.jpg
2021-11-08 19:27:26,953 django.request WARNING  Not Found: /media/post_pics/Без_названия_sIJlGzm.jfif
2021-11-08 19:27:26,958 django.request WARNING  Not Found: /media/post_pics/1016619_ywWHyLs.jpg
2021-11-08 19:28:50,484 django.request ERROR    Internal Server Error: /admin/login/
Traceback (most recent call last):
  File "C:\Users\tarlo\Desktop\Code\DJANGO\instamiligram\venv\lib\site-packages\django\core\handlers\exception.py", line 47, in inner
    response = get_response(request)
  File "C:\Users\tarlo\Desktop\Code\DJANGO\instamiligram\venv\lib\site-packages\django\core\handlers\base.py", line 181, in _get_response
    response = wrapped_callback(request, *callback_args, **callback_kwargs)
  File "C:\Users\tarlo\Desktop\Code\DJANGO\instamiligram\venv\lib\site-packages\django\views\decorators\cache.py", line 44, in _wrapped_view_func
    response = view_func(request, *args, **kwargs)
  File "C:\Users\tarlo\Desktop\Code\DJANGO\instamiligram\venv\lib\site-packages\django\contrib\admin\sites.py", line 414, in login
    return LoginView.as_view(**defaults)(request)
  File "C:\Users\tarlo\Desktop\Code\DJANGO\instamiligram\venv\lib\site-packages\django\views\generic\base.py", line 70, in view
    return self.dispatch(request, *args, **kwargs)
  File "C:\Users\tarlo\Desktop\Code\DJANGO\instamiligram\venv\lib\site-packages\django\utils\decorators.py", line 43, in _wrapper
    return bound_method(*args, **kwargs)
  File "C:\Users\tarlo\Desktop\Code\DJANGO\instamiligram\venv\lib\site-packages\django\views\decorators\debug.py", line 89, in sensitive_post_parameters_wrapper
    return view(request, *args, **kwargs)
  File "C:\Users\tarlo\Desktop\Code\DJANGO\instamiligram\venv\lib\site-packages\django\utils\decorators.py", line 43, in _wrapper
    return bound_method(*args, **kwargs)
  File "C:\Users\tarlo\Desktop\Code\DJANGO\instamiligram\venv\lib\site-packages\django\utils\decorators.py", line 130, in _wrapped_view
    response = view_func(request, *args, **kwargs)
  File "C:\Users\tarlo\Desktop\Code\DJANGO\instamiligram\venv\lib\site-packages\django\utils\decorators.py", line 43, in _wrapper
    return bound_method(*args, **kwargs)
  File "C:\Users\tarlo\Desktop\Code\DJANGO\instamiligram\venv\lib\site-packages\django\views\decorators\cache.py", line 44, in _wrapped_view_func
    response = view_func(request, *args, **kwargs)
  File "C:\Users\tarlo\Desktop\Code\DJANGO\instamiligram\venv\lib\site-packages\django\contrib\auth\views.py", line 63, in dispatch
    return super().dispatch(request, *args, **kwargs)
  File "C:\Users\tarlo\Desktop\Code\DJANGO\instamiligram\venv\lib\site-packages\django\views\generic\base.py", line 98, in dispatch
    return handler(request, *args, **kwargs)
  File "C:\Users\tarlo\Desktop\Code\DJANGO\instamiligram\venv\lib\site-packages\django\views\generic\edit.py", line 142, in post
    return self.form_valid(form)
  File "C:\Users\tarlo\Desktop\Code\DJANGO\instamiligram\venv\lib\site-packages\django\contrib\auth\views.py", line 92, in form_valid
    auth_login(self.request, form.get_user())
  File "C:\Users\tarlo\Desktop\Code\DJANGO\instamiligram\venv\lib\site-packages\django\contrib\auth\__init__.py", line 135, in login
    user_logged_in.send(sender=user.__class__, request=request, user=user)
  File "C:\Users\tarlo\Desktop\Code\DJANGO\instamiligram\venv\lib\site-packages\django\dispatch\dispatcher.py", line 180, in send
    return [
  File "C:\Users\tarlo\Desktop\Code\DJANGO\instamiligram\venv\lib\site-packages\django\dispatch\dispatcher.py", line 181, in <listcomp>
    (receiver, receiver(signal=self, sender=sender, **named))
  File "C:\Users\tarlo\Desktop\Code\DJANGO\instamiligram\venv\lib\site-packages\django\contrib\auth\models.py", line 22, in update_last_login
    user.save(update_fields=['last_login'])
  File "C:\Users\tarlo\Desktop\Code\DJANGO\instamiligram\venv\lib\site-packages\django\contrib\auth\base_user.py", line 67, in save
    super().save(*args, **kwargs)
  File "C:\Users\tarlo\Desktop\Code\DJANGO\instamiligram\venv\lib\site-packages\django\db\models\base.py", line 726, in save
    self.save_base(using=using, force_insert=force_insert,
  File "C:\Users\tarlo\Desktop\Code\DJANGO\instamiligram\venv\lib\site-packages\django\db\models\base.py", line 774, in save_base
    post_save.send(
  File "C:\Users\tarlo\Desktop\Code\DJANGO\instamiligram\venv\lib\site-packages\django\dispatch\dispatcher.py", line 180, in send
    return [
  File "C:\Users\tarlo\Desktop\Code\DJANGO\instamiligram\venv\lib\site-packages\django\dispatch\dispatcher.py", line 181, in <listcomp>
    (receiver, receiver(signal=self, sender=sender, **named))
  File "C:\Users\tarlo\Desktop\Code\DJANGO\instamiligram\users\signals.py", line 15, in save_profile
    instance.profile.save()
  File "C:\Users\tarlo\Desktop\Code\DJANGO\instamiligram\users\models.py", line 26, in save
    img = Image.open(self.image.path)
  File "C:\Users\tarlo\Desktop\Code\DJANGO\instamiligram\venv\lib\site-packages\PIL\Image.py", line 2975, in open
    fp = builtins.open(filename, "rb")
FileNotFoundError: [Errno 2] No such file or directory: 'C:\\Users\\tarlo\\Desktop\\Code\\DJANGO\\instamiligram\\media\\profile_pics\\650812.jpg'
2021-11-08 19:29:53,313 django.request ERROR    Internal Server Error: /admin/login/
Traceback (most recent call last):
  File "C:\Users\tarlo\Desktop\Code\DJANGO\instamiligram\venv\lib\site-packages\django\core\handlers\exception.py", line 47, in inner
    response = get_response(request)
  File "C:\Users\tarlo\Desktop\Code\DJANGO\instamiligram\venv\lib\site-packages\django\core\handlers\base.py", line 181, in _get_response
    response = wrapped_callback(request, *callback_args, **callback_kwargs)
  File "C:\Users\tarlo\Desktop\Code\DJANGO\instamiligram\venv\lib\site-packages\django\views\decorators\cache.py", line 44, in _wrapped_view_func
    response = view_func(request, *args, **kwargs)
  File "C:\Users\tarlo\Desktop\Code\DJANGO\instamiligram\venv\lib\site-packages\django\contrib\admin\sites.py", line 414, in login
    return LoginView.as_view(**defaults)(request)
  File "C:\Users\tarlo\Desktop\Code\DJANGO\instamiligram\venv\lib\site-packages\django\views\generic\base.py", line 70, in view
    return self.dispatch(request, *args, **kwargs)
  File "C:\Users\tarlo\Desktop\Code\DJANGO\instamiligram\venv\lib\site-packages\django\utils\decorators.py", line 43, in _wrapper
    return bound_method(*args, **kwargs)
  File "C:\Users\tarlo\Desktop\Code\DJANGO\instamiligram\venv\lib\site-packages\django\views\decorators\debug.py", line 89, in sensitive_post_parameters_wrapper
    return view(request, *args, **kwargs)
  File "C:\Users\tarlo\Desktop\Code\DJANGO\instamiligram\venv\lib\site-packages\django\utils\decorators.py", line 43, in _wrapper
    return bound_method(*args, **kwargs)
  File "C:\Users\tarlo\Desktop\Code\DJANGO\instamiligram\venv\lib\site-packages\django\utils\decorators.py", line 130, in _wrapped_view
    response = view_func(request, *args, **kwargs)
  File "C:\Users\tarlo\Desktop\Code\DJANGO\instamiligram\venv\lib\site-packages\django\utils\decorators.py", line 43, in _wrapper
    return bound_method(*args, **kwargs)
  File "C:\Users\tarlo\Desktop\Code\DJANGO\instamiligram\venv\lib\site-packages\django\views\decorators\cache.py", line 44, in _wrapped_view_func
    response = view_func(request, *args, **kwargs)
  File "C:\Users\tarlo\Desktop\Code\DJANGO\instamiligram\venv\lib\site-packages\django\contrib\auth\views.py", line 63, in dispatch
    return super().dispatch(request, *args, **kwargs)
  File "C:\Users\tarlo\Desktop\Code\DJANGO\instamiligram\venv\lib\site-packages\django\views\generic\base.py", line 98, in dispatch
    return handler(request, *args, **kwargs)
  File "C:\Users\tarlo\Desktop\Code\DJANGO\instamiligram\venv\lib\site-packages\django\views\generic\edit.py", line 142, in post
    return self.form_valid(form)
  File "C:\Users\tarlo\Desktop\Code\DJANGO\instamiligram\venv\lib\site-packages\django\contrib\auth\views.py", line 92, in form_valid
    auth_login(self.request, form.get_user())
  File "C:\Users\tarlo\Desktop\Code\DJANGO\instamiligram\venv\lib\site-packages\django\contrib\auth\__init__.py", line 135, in login
    user_logged_in.send(sender=user.__class__, request=request, user=user)
  File "C:\Users\tarlo\Desktop\Code\DJANGO\instamiligram\venv\lib\site-packages\django\dispatch\dispatcher.py", line 180, in send
    return [
  File "C:\Users\tarlo\Desktop\Code\DJANGO\instamiligram\venv\lib\site-packages\django\dispatch\dispatcher.py", line 181, in <listcomp>
    (receiver, receiver(signal=self, sender=sender, **named))
  File "C:\Users\tarlo\Desktop\Code\DJANGO\instamiligram\venv\lib\site-packages\django\contrib\auth\models.py", line 22, in update_last_login
    user.save(update_fields=['last_login'])
  File "C:\Users\tarlo\Desktop\Code\DJANGO\instamiligram\venv\lib\site-packages\django\contrib\auth\base_user.py", line 67, in save
    super().save(*args, **kwargs)
  File "C:\Users\tarlo\Desktop\Code\DJANGO\instamiligram\venv\lib\site-packages\django\db\models\base.py", line 726, in save
    self.save_base(using=using, force_insert=force_insert,
  File "C:\Users\tarlo\Desktop\Code\DJANGO\instamiligram\venv\lib\site-packages\django\db\models\base.py", line 774, in save_base
    post_save.send(
  File "C:\Users\tarlo\Desktop\Code\DJANGO\instamiligram\venv\lib\site-packages\django\dispatch\dispatcher.py", line 180, in send
    return [
  File "C:\Users\tarlo\Desktop\Code\DJANGO\instamiligram\venv\lib\site-packages\django\dispatch\dispatcher.py", line 181, in <listcomp>
    (receiver, receiver(signal=self, sender=sender, **named))
  File "C:\Users\tarlo\Desktop\Code\DJANGO\instamiligram\users\signals.py", line 15, in save_profile
    instance.profile.save()
  File "C:\Users\tarlo\Desktop\Code\DJANGO\instamiligram\users\models.py", line 26, in save
    img = Image.open(self.image.path)
  File "C:\Users\tarlo\Desktop\Code\DJANGO\instamiligram\venv\lib\site-packages\PIL\Image.py", line 2975, in open
    fp = builtins.open(filename, "rb")
FileNotFoundError: [Errno 2] No such file or directory: 'C:\\Users\\tarlo\\Desktop\\Code\\DJANGO\\instamiligram\\media\\profile_pics\\650812.jpg'
2021-11-08 19:30:10,442 django.request ERROR    Internal Server Error: /admin/login/
Traceback (most recent call last):
  File "C:\Users\tarlo\Desktop\Code\DJANGO\instamiligram\venv\lib\site-packages\PIL\JpegImagePlugin.py", line 629, in _save
    rawmode = RAWMODE[im.mode]
KeyError: 'RGBA'

The above exception was the direct cause of the following exception:

Traceback (most recent call last):
  File "C:\Users\tarlo\Desktop\Code\DJANGO\instamiligram\venv\lib\site-packages\django\core\handlers\exception.py", line 47, in inner
    response = get_response(request)
  File "C:\Users\tarlo\Desktop\Code\DJANGO\instamiligram\venv\lib\site-packages\django\core\handlers\base.py", line 181, in _get_response
    response = wrapped_callback(request, *callback_args, **callback_kwargs)
  File "C:\Users\tarlo\Desktop\Code\DJANGO\instamiligram\venv\lib\site-packages\django\views\decorators\cache.py", line 44, in _wrapped_view_func
    response = view_func(request, *args, **kwargs)
  File "C:\Users\tarlo\Desktop\Code\DJANGO\instamiligram\venv\lib\site-packages\django\contrib\admin\sites.py", line 414, in login
    return LoginView.as_view(**defaults)(request)
  File "C:\Users\tarlo\Desktop\Code\DJANGO\instamiligram\venv\lib\site-packages\django\views\generic\base.py", line 70, in view
    return self.dispatch(request, *args, **kwargs)
  File "C:\Users\tarlo\Desktop\Code\DJANGO\instamiligram\venv\lib\site-packages\django\utils\decorators.py", line 43, in _wrapper
    return bound_method(*args, **kwargs)
  File "C:\Users\tarlo\Desktop\Code\DJANGO\instamiligram\venv\lib\site-packages\django\views\decorators\debug.py", line 89, in sensitive_post_parameters_wrapper
    return view(request, *args, **kwargs)
  File "C:\Users\tarlo\Desktop\Code\DJANGO\instamiligram\venv\lib\site-packages\django\utils\decorators.py", line 43, in _wrapper
    return bound_method(*args, **kwargs)
  File "C:\Users\tarlo\Desktop\Code\DJANGO\instamiligram\venv\lib\site-packages\django\utils\decorators.py", line 130, in _wrapped_view
    response = view_func(request, *args, **kwargs)
  File "C:\Users\tarlo\Desktop\Code\DJANGO\instamiligram\venv\lib\site-packages\django\utils\decorators.py", line 43, in _wrapper
    return bound_method(*args, **kwargs)
  File "C:\Users\tarlo\Desktop\Code\DJANGO\instamiligram\venv\lib\site-packages\django\views\decorators\cache.py", line 44, in _wrapped_view_func
    response = view_func(request, *args, **kwargs)
  File "C:\Users\tarlo\Desktop\Code\DJANGO\instamiligram\venv\lib\site-packages\django\contrib\auth\views.py", line 63, in dispatch
    return super().dispatch(request, *args, **kwargs)
  File "C:\Users\tarlo\Desktop\Code\DJANGO\instamiligram\venv\lib\site-packages\django\views\generic\base.py", line 98, in dispatch
    return handler(request, *args, **kwargs)
  File "C:\Users\tarlo\Desktop\Code\DJANGO\instamiligram\venv\lib\site-packages\django\views\generic\edit.py", line 142, in post
    return self.form_valid(form)
  File "C:\Users\tarlo\Desktop\Code\DJANGO\instamiligram\venv\lib\site-packages\django\contrib\auth\views.py", line 92, in form_valid
    auth_login(self.request, form.get_user())
  File "C:\Users\tarlo\Desktop\Code\DJANGO\instamiligram\venv\lib\site-packages\django\contrib\auth\__init__.py", line 135, in login
    user_logged_in.send(sender=user.__class__, request=request, user=user)
  File "C:\Users\tarlo\Desktop\Code\DJANGO\instamiligram\venv\lib\site-packages\django\dispatch\dispatcher.py", line 180, in send
    return [
  File "C:\Users\tarlo\Desktop\Code\DJANGO\instamiligram\venv\lib\site-packages\django\dispatch\dispatcher.py", line 181, in <listcomp>
    (receiver, receiver(signal=self, sender=sender, **named))
  File "C:\Users\tarlo\Desktop\Code\DJANGO\instamiligram\venv\lib\site-packages\django\contrib\auth\models.py", line 22, in update_last_login
    user.save(update_fields=['last_login'])
  File "C:\Users\tarlo\Desktop\Code\DJANGO\instamiligram\venv\lib\site-packages\django\contrib\auth\base_user.py", line 67, in save
    super().save(*args, **kwargs)
  File "C:\Users\tarlo\Desktop\Code\DJANGO\instamiligram\venv\lib\site-packages\django\db\models\base.py", line 726, in save
    self.save_base(using=using, force_insert=force_insert,
  File "C:\Users\tarlo\Desktop\Code\DJANGO\instamiligram\venv\lib\site-packages\django\db\models\base.py", line 774, in save_base
    post_save.send(
  File "C:\Users\tarlo\Desktop\Code\DJANGO\instamiligram\venv\lib\site-packages\django\dispatch\dispatcher.py", line 180, in send
    return [
  File "C:\Users\tarlo\Desktop\Code\DJANGO\instamiligram\venv\lib\site-packages\django\dispatch\dispatcher.py", line 181, in <listcomp>
    (receiver, receiver(signal=self, sender=sender, **named))
  File "C:\Users\tarlo\Desktop\Code\DJANGO\instamiligram\users\signals.py", line 15, in save_profile
    instance.profile.save()
  File "C:\Users\tarlo\Desktop\Code\DJANGO\instamiligram\users\models.py", line 30, in save
    i.save(self.image.path)
  File "C:\Users\tarlo\Desktop\Code\DJANGO\instamiligram\venv\lib\site-packages\PIL\Image.py", line 2240, in save
    save_handler(self, fp, filename)
  File "C:\Users\tarlo\Desktop\Code\DJANGO\instamiligram\venv\lib\site-packages\PIL\JpegImagePlugin.py", line 631, in _save
    raise OSError(f"cannot write mode {im.mode} as JPEG") from e
OSError: cannot write mode RGBA as JPEG
2021-11-08 19:44:18,323 django.request ERROR    Internal Server Error: /profile/tarlo
Traceback (most recent call last):
  File "C:\Users\tarlo\Desktop\Code\DJANGO\instamiligram\venv\lib\site-packages\django\template\base.py", line 470, in parse
    compile_func = self.tags[command]
KeyError: 'get_user_posts'

During handling of the above exception, another exception occurred:

Traceback (most recent call last):
  File "C:\Users\tarlo\Desktop\Code\DJANGO\instamiligram\venv\lib\site-packages\django\core\handlers\exception.py", line 47, in inner
    response = get_response(request)
  File "C:\Users\tarlo\Desktop\Code\DJANGO\instamiligram\venv\lib\site-packages\django\core\handlers\base.py", line 181, in _get_response
    response = wrapped_callback(request, *callback_args, **callback_kwargs)
  File "C:\Users\tarlo\Desktop\Code\DJANGO\instamiligram\venv\lib\site-packages\django\views\generic\base.py", line 70, in view
    return self.dispatch(request, *args, **kwargs)
  File "C:\Users\tarlo\Desktop\Code\DJANGO\instamiligram\venv\lib\site-packages\django\views\generic\base.py", line 98, in dispatch
    return handler(request, *args, **kwargs)
  File "C:\Users\tarlo\Desktop\Code\DJANGO\instamiligram\users\views.py", line 108, in get
    return render(request, "users/profile.html", {"user": User.objects.filter(username=username).first()})
  File "C:\Users\tarlo\Desktop\Code\DJANGO\instamiligram\venv\lib\site-packages\django\shortcuts.py", line 19, in render
    content = loader.render_to_string(template_name, context, request, using=using)
  File "C:\Users\tarlo\Desktop\Code\DJANGO\instamiligram\venv\lib\site-packages\django\template\loader.py", line 61, in render_to_string
    template = get_template(template_name, using=using)
  File "C:\Users\tarlo\Desktop\Code\DJANGO\instamiligram\venv\lib\site-packages\django\template\loader.py", line 15, in get_template
    return engine.get_template(template_name)
  File "C:\Users\tarlo\Desktop\Code\DJANGO\instamiligram\venv\lib\site-packages\django\template\backends\django.py", line 34, in get_template
    return Template(self.engine.get_template(template_name), self)
  File "C:\Users\tarlo\Desktop\Code\DJANGO\instamiligram\venv\lib\site-packages\django\template\engine.py", line 143, in get_template
    template, origin = self.find_template(template_name)
  File "C:\Users\tarlo\Desktop\Code\DJANGO\instamiligram\venv\lib\site-packages\django\template\engine.py", line 125, in find_template
    template = loader.get_template(name, skip=skip)
  File "C:\Users\tarlo\Desktop\Code\DJANGO\instamiligram\venv\lib\site-packages\django\template\loaders\base.py", line 29, in get_template
    return Template(
  File "C:\Users\tarlo\Desktop\Code\DJANGO\instamiligram\venv\lib\site-packages\django\template\base.py", line 155, in __init__
    self.nodelist = self.compile_nodelist()
  File "C:\Users\tarlo\Desktop\Code\DJANGO\instamiligram\venv\lib\site-packages\django\template\base.py", line 193, in compile_nodelist
    return parser.parse()
  File "C:\Users\tarlo\Desktop\Code\DJANGO\instamiligram\venv\lib\site-packages\django\template\base.py", line 478, in parse
    raise self.error(token, e)
  File "C:\Users\tarlo\Desktop\Code\DJANGO\instamiligram\venv\lib\site-packages\django\template\base.py", line 476, in parse
    compiled_result = compile_func(self, token)
  File "C:\Users\tarlo\Desktop\Code\DJANGO\instamiligram\venv\lib\site-packages\django\template\loader_tags.py", line 278, in do_extends
    nodelist = parser.parse()
  File "C:\Users\tarlo\Desktop\Code\DJANGO\instamiligram\venv\lib\site-packages\django\template\base.py", line 478, in parse
    raise self.error(token, e)
  File "C:\Users\tarlo\Desktop\Code\DJANGO\instamiligram\venv\lib\site-packages\django\template\base.py", line 476, in parse
    compiled_result = compile_func(self, token)
  File "C:\Users\tarlo\Desktop\Code\DJANGO\instamiligram\venv\lib\site-packages\django\template\loader_tags.py", line 216, in do_block
    nodelist = parser.parse(('endblock',))
  File "C:\Users\tarlo\Desktop\Code\DJANGO\instamiligram\venv\lib\site-packages\django\template\base.py", line 472, in parse
    self.invalid_block_tag(token, command, parse_until)
  File "C:\Users\tarlo\Desktop\Code\DJANGO\instamiligram\venv\lib\site-packages\django\template\base.py", line 522, in invalid_block_tag
    raise self.error(
django.template.exceptions.TemplateSyntaxError: Invalid block tag on line 4: 'get_user_posts', expected 'endblock'. Did you forget to register or load this tag?
2021-11-08 19:45:46,710 django.request ERROR    Internal Server Error: /profile/tarlo
Traceback (most recent call last):
  File "C:\Users\tarlo\Desktop\Code\DJANGO\instamiligram\venv\lib\site-packages\django\template\base.py", line 470, in parse
    compile_func = self.tags[command]
KeyError: 'get_user_posts'

During handling of the above exception, another exception occurred:

Traceback (most recent call last):
  File "C:\Users\tarlo\Desktop\Code\DJANGO\instamiligram\venv\lib\site-packages\django\core\handlers\exception.py", line 47, in inner
    response = get_response(request)
  File "C:\Users\tarlo\Desktop\Code\DJANGO\instamiligram\venv\lib\site-packages\django\core\handlers\base.py", line 181, in _get_response
    response = wrapped_callback(request, *callback_args, **callback_kwargs)
  File "C:\Users\tarlo\Desktop\Code\DJANGO\instamiligram\venv\lib\site-packages\django\views\generic\base.py", line 70, in view
    return self.dispatch(request, *args, **kwargs)
  File "C:\Users\tarlo\Desktop\Code\DJANGO\instamiligram\venv\lib\site-packages\django\views\generic\base.py", line 98, in dispatch
    return handler(request, *args, **kwargs)
  File "C:\Users\tarlo\Desktop\Code\DJANGO\instamiligram\users\views.py", line 108, in get
    return render(request, "users/profile.html", {"user": User.objects.filter(username=username).first()})
  File "C:\Users\tarlo\Desktop\Code\DJANGO\instamiligram\venv\lib\site-packages\django\shortcuts.py", line 19, in render
    content = loader.render_to_string(template_name, context, request, using=using)
  File "C:\Users\tarlo\Desktop\Code\DJANGO\instamiligram\venv\lib\site-packages\django\template\loader.py", line 61, in render_to_string
    template = get_template(template_name, using=using)
  File "C:\Users\tarlo\Desktop\Code\DJANGO\instamiligram\venv\lib\site-packages\django\template\loader.py", line 15, in get_template
    return engine.get_template(template_name)
  File "C:\Users\tarlo\Desktop\Code\DJANGO\instamiligram\venv\lib\site-packages\django\template\backends\django.py", line 34, in get_template
    return Template(self.engine.get_template(template_name), self)
  File "C:\Users\tarlo\Desktop\Code\DJANGO\instamiligram\venv\lib\site-packages\django\template\engine.py", line 143, in get_template
    template, origin = self.find_template(template_name)
  File "C:\Users\tarlo\Desktop\Code\DJANGO\instamiligram\venv\lib\site-packages\django\template\engine.py", line 125, in find_template
    template = loader.get_template(name, skip=skip)
  File "C:\Users\tarlo\Desktop\Code\DJANGO\instamiligram\venv\lib\site-packages\django\template\loaders\base.py", line 29, in get_template
    return Template(
  File "C:\Users\tarlo\Desktop\Code\DJANGO\instamiligram\venv\lib\site-packages\django\template\base.py", line 155, in __init__
    self.nodelist = self.compile_nodelist()
  File "C:\Users\tarlo\Desktop\Code\DJANGO\instamiligram\venv\lib\site-packages\django\template\base.py", line 193, in compile_nodelist
    return parser.parse()
  File "C:\Users\tarlo\Desktop\Code\DJANGO\instamiligram\venv\lib\site-packages\django\template\base.py", line 478, in parse
    raise self.error(token, e)
  File "C:\Users\tarlo\Desktop\Code\DJANGO\instamiligram\venv\lib\site-packages\django\template\base.py", line 476, in parse
    compiled_result = compile_func(self, token)
  File "C:\Users\tarlo\Desktop\Code\DJANGO\instamiligram\venv\lib\site-packages\django\template\loader_tags.py", line 278, in do_extends
    nodelist = parser.parse()
  File "C:\Users\tarlo\Desktop\Code\DJANGO\instamiligram\venv\lib\site-packages\django\template\base.py", line 478, in parse
    raise self.error(token, e)
  File "C:\Users\tarlo\Desktop\Code\DJANGO\instamiligram\venv\lib\site-packages\django\template\base.py", line 476, in parse
    compiled_result = compile_func(self, token)
  File "C:\Users\tarlo\Desktop\Code\DJANGO\instamiligram\venv\lib\site-packages\django\template\loader_tags.py", line 216, in do_block
    nodelist = parser.parse(('endblock',))
  File "C:\Users\tarlo\Desktop\Code\DJANGO\instamiligram\venv\lib\site-packages\django\template\base.py", line 472, in parse
    self.invalid_block_tag(token, command, parse_until)
  File "C:\Users\tarlo\Desktop\Code\DJANGO\instamiligram\venv\lib\site-packages\django\template\base.py", line 522, in invalid_block_tag
    raise self.error(
django.template.exceptions.TemplateSyntaxError: Invalid block tag on line 4: 'get_user_posts', expected 'endblock'. Did you forget to register or load this tag?
2021-11-08 19:45:54,244 django.request ERROR    Internal Server Error: /profile/koji
Traceback (most recent call last):
  File "C:\Users\tarlo\Desktop\Code\DJANGO\instamiligram\venv\lib\site-packages\django\template\base.py", line 470, in parse
    compile_func = self.tags[command]
KeyError: 'get_user_posts'

During handling of the above exception, another exception occurred:

Traceback (most recent call last):
  File "C:\Users\tarlo\Desktop\Code\DJANGO\instamiligram\venv\lib\site-packages\django\core\handlers\exception.py", line 47, in inner
    response = get_response(request)
  File "C:\Users\tarlo\Desktop\Code\DJANGO\instamiligram\venv\lib\site-packages\django\core\handlers\base.py", line 181, in _get_response
    response = wrapped_callback(request, *callback_args, **callback_kwargs)
  File "C:\Users\tarlo\Desktop\Code\DJANGO\instamiligram\venv\lib\site-packages\django\views\generic\base.py", line 70, in view
    return self.dispatch(request, *args, **kwargs)
  File "C:\Users\tarlo\Desktop\Code\DJANGO\instamiligram\venv\lib\site-packages\django\views\generic\base.py", line 98, in dispatch
    return handler(request, *args, **kwargs)
  File "C:\Users\tarlo\Desktop\Code\DJANGO\instamiligram\users\views.py", line 108, in get
    return render(request, "users/profile.html", {"user": User.objects.filter(username=username).first()})
  File "C:\Users\tarlo\Desktop\Code\DJANGO\instamiligram\venv\lib\site-packages\django\shortcuts.py", line 19, in render
    content = loader.render_to_string(template_name, context, request, using=using)
  File "C:\Users\tarlo\Desktop\Code\DJANGO\instamiligram\venv\lib\site-packages\django\template\loader.py", line 61, in render_to_string
    template = get_template(template_name, using=using)
  File "C:\Users\tarlo\Desktop\Code\DJANGO\instamiligram\venv\lib\site-packages\django\template\loader.py", line 15, in get_template
    return engine.get_template(template_name)
  File "C:\Users\tarlo\Desktop\Code\DJANGO\instamiligram\venv\lib\site-packages\django\template\backends\django.py", line 34, in get_template
    return Template(self.engine.get_template(template_name), self)
  File "C:\Users\tarlo\Desktop\Code\DJANGO\instamiligram\venv\lib\site-packages\django\template\engine.py", line 143, in get_template
    template, origin = self.find_template(template_name)
  File "C:\Users\tarlo\Desktop\Code\DJANGO\instamiligram\venv\lib\site-packages\django\template\engine.py", line 125, in find_template
    template = loader.get_template(name, skip=skip)
  File "C:\Users\tarlo\Desktop\Code\DJANGO\instamiligram\venv\lib\site-packages\django\template\loaders\base.py", line 29, in get_template
    return Template(
  File "C:\Users\tarlo\Desktop\Code\DJANGO\instamiligram\venv\lib\site-packages\django\template\base.py", line 155, in __init__
    self.nodelist = self.compile_nodelist()
  File "C:\Users\tarlo\Desktop\Code\DJANGO\instamiligram\venv\lib\site-packages\django\template\base.py", line 193, in compile_nodelist
    return parser.parse()
  File "C:\Users\tarlo\Desktop\Code\DJANGO\instamiligram\venv\lib\site-packages\django\template\base.py", line 478, in parse
    raise self.error(token, e)
  File "C:\Users\tarlo\Desktop\Code\DJANGO\instamiligram\venv\lib\site-packages\django\template\base.py", line 476, in parse
    compiled_result = compile_func(self, token)
  File "C:\Users\tarlo\Desktop\Code\DJANGO\instamiligram\venv\lib\site-packages\django\template\loader_tags.py", line 278, in do_extends
    nodelist = parser.parse()
  File "C:\Users\tarlo\Desktop\Code\DJANGO\instamiligram\venv\lib\site-packages\django\template\base.py", line 478, in parse
    raise self.error(token, e)
  File "C:\Users\tarlo\Desktop\Code\DJANGO\instamiligram\venv\lib\site-packages\django\template\base.py", line 476, in parse
    compiled_result = compile_func(self, token)
  File "C:\Users\tarlo\Desktop\Code\DJANGO\instamiligram\venv\lib\site-packages\django\template\loader_tags.py", line 216, in do_block
    nodelist = parser.parse(('endblock',))
  File "C:\Users\tarlo\Desktop\Code\DJANGO\instamiligram\venv\lib\site-packages\django\template\base.py", line 472, in parse
    self.invalid_block_tag(token, command, parse_until)
  File "C:\Users\tarlo\Desktop\Code\DJANGO\instamiligram\venv\lib\site-packages\django\template\base.py", line 522, in invalid_block_tag
    raise self.error(
django.template.exceptions.TemplateSyntaxError: Invalid block tag on line 4: 'get_user_posts', expected 'endblock'. Did you forget to register or load this tag?
2021-11-08 19:47:14,654 django.request ERROR    Internal Server Error: /profile/koji
Traceback (most recent call last):
  File "C:\Users\tarlo\Desktop\Code\DJANGO\instamiligram\venv\lib\site-packages\django\template\base.py", line 470, in parse
    compile_func = self.tags[command]
KeyError: 'get_user_posts'

During handling of the above exception, another exception occurred:

Traceback (most recent call last):
  File "C:\Users\tarlo\Desktop\Code\DJANGO\instamiligram\venv\lib\site-packages\django\core\handlers\exception.py", line 47, in inner
    response = get_response(request)
  File "C:\Users\tarlo\Desktop\Code\DJANGO\instamiligram\venv\lib\site-packages\django\core\handlers\base.py", line 181, in _get_response
    response = wrapped_callback(request, *callback_args, **callback_kwargs)
  File "C:\Users\tarlo\Desktop\Code\DJANGO\instamiligram\venv\lib\site-packages\django\views\generic\base.py", line 70, in view
    return self.dispatch(request, *args, **kwargs)
  File "C:\Users\tarlo\Desktop\Code\DJANGO\instamiligram\venv\lib\site-packages\django\views\generic\base.py", line 98, in dispatch
    return handler(request, *args, **kwargs)
  File "C:\Users\tarlo\Desktop\Code\DJANGO\instamiligram\users\views.py", line 108, in get
    return render(request, "users/profile.html", {"user": User.objects.filter(username=username).first()})
  File "C:\Users\tarlo\Desktop\Code\DJANGO\instamiligram\venv\lib\site-packages\django\shortcuts.py", line 19, in render
    content = loader.render_to_string(template_name, context, request, using=using)
  File "C:\Users\tarlo\Desktop\Code\DJANGO\instamiligram\venv\lib\site-packages\django\template\loader.py", line 61, in render_to_string
    template = get_template(template_name, using=using)
  File "C:\Users\tarlo\Desktop\Code\DJANGO\instamiligram\venv\lib\site-packages\django\template\loader.py", line 15, in get_template
    return engine.get_template(template_name)
  File "C:\Users\tarlo\Desktop\Code\DJANGO\instamiligram\venv\lib\site-packages\django\template\backends\django.py", line 34, in get_template
    return Template(self.engine.get_template(template_name), self)
  File "C:\Users\tarlo\Desktop\Code\DJANGO\instamiligram\venv\lib\site-packages\django\template\engine.py", line 143, in get_template
    template, origin = self.find_template(template_name)
  File "C:\Users\tarlo\Desktop\Code\DJANGO\instamiligram\venv\lib\site-packages\django\template\engine.py", line 125, in find_template
    template = loader.get_template(name, skip=skip)
  File "C:\Users\tarlo\Desktop\Code\DJANGO\instamiligram\venv\lib\site-packages\django\template\loaders\base.py", line 29, in get_template
    return Template(
  File "C:\Users\tarlo\Desktop\Code\DJANGO\instamiligram\venv\lib\site-packages\django\template\base.py", line 155, in __init__
    self.nodelist = self.compile_nodelist()
  File "C:\Users\tarlo\Desktop\Code\DJANGO\instamiligram\venv\lib\site-packages\django\template\base.py", line 193, in compile_nodelist
    return parser.parse()
  File "C:\Users\tarlo\Desktop\Code\DJANGO\instamiligram\venv\lib\site-packages\django\template\base.py", line 478, in parse
    raise self.error(token, e)
  File "C:\Users\tarlo\Desktop\Code\DJANGO\instamiligram\venv\lib\site-packages\django\template\base.py", line 476, in parse
    compiled_result = compile_func(self, token)
  File "C:\Users\tarlo\Desktop\Code\DJANGO\instamiligram\venv\lib\site-packages\django\template\loader_tags.py", line 278, in do_extends
    nodelist = parser.parse()
  File "C:\Users\tarlo\Desktop\Code\DJANGO\instamiligram\venv\lib\site-packages\django\template\base.py", line 472, in parse
    self.invalid_block_tag(token, command, parse_until)
  File "C:\Users\tarlo\Desktop\Code\DJANGO\instamiligram\venv\lib\site-packages\django\template\base.py", line 531, in invalid_block_tag
    raise self.error(
django.template.exceptions.TemplateSyntaxError: Invalid block tag on line 4: 'get_user_posts'. Did you forget to register or load this tag?
2021-11-08 19:47:53,407 django.request ERROR    Internal Server Error: /profile/koji
Traceback (most recent call last):
  File "C:\Users\tarlo\Desktop\Code\DJANGO\instamiligram\venv\lib\site-packages\django\template\base.py", line 470, in parse
    compile_func = self.tags[command]
KeyError: 'get_user_posts'

During handling of the above exception, another exception occurred:

Traceback (most recent call last):
  File "C:\Users\tarlo\Desktop\Code\DJANGO\instamiligram\venv\lib\site-packages\django\core\handlers\exception.py", line 47, in inner
    response = get_response(request)
  File "C:\Users\tarlo\Desktop\Code\DJANGO\instamiligram\venv\lib\site-packages\django\core\handlers\base.py", line 181, in _get_response
    response = wrapped_callback(request, *callback_args, **callback_kwargs)
  File "C:\Users\tarlo\Desktop\Code\DJANGO\instamiligram\venv\lib\site-packages\django\views\generic\base.py", line 70, in view
    return self.dispatch(request, *args, **kwargs)
  File "C:\Users\tarlo\Desktop\Code\DJANGO\instamiligram\venv\lib\site-packages\django\views\generic\base.py", line 98, in dispatch
    return handler(request, *args, **kwargs)
  File "C:\Users\tarlo\Desktop\Code\DJANGO\instamiligram\users\views.py", line 108, in get
    return render(request, "users/profile.html", {"user": User.objects.filter(username=username).first()})
  File "C:\Users\tarlo\Desktop\Code\DJANGO\instamiligram\venv\lib\site-packages\django\shortcuts.py", line 19, in render
    content = loader.render_to_string(template_name, context, request, using=using)
  File "C:\Users\tarlo\Desktop\Code\DJANGO\instamiligram\venv\lib\site-packages\django\template\loader.py", line 61, in render_to_string
    template = get_template(template_name, using=using)
  File "C:\Users\tarlo\Desktop\Code\DJANGO\instamiligram\venv\lib\site-packages\django\template\loader.py", line 15, in get_template
    return engine.get_template(template_name)
  File "C:\Users\tarlo\Desktop\Code\DJANGO\instamiligram\venv\lib\site-packages\django\template\backends\django.py", line 34, in get_template
    return Template(self.engine.get_template(template_name), self)
  File "C:\Users\tarlo\Desktop\Code\DJANGO\instamiligram\venv\lib\site-packages\django\template\engine.py", line 143, in get_template
    template, origin = self.find_template(template_name)
  File "C:\Users\tarlo\Desktop\Code\DJANGO\instamiligram\venv\lib\site-packages\django\template\engine.py", line 125, in find_template
    template = loader.get_template(name, skip=skip)
  File "C:\Users\tarlo\Desktop\Code\DJANGO\instamiligram\venv\lib\site-packages\django\template\loaders\base.py", line 29, in get_template
    return Template(
  File "C:\Users\tarlo\Desktop\Code\DJANGO\instamiligram\venv\lib\site-packages\django\template\base.py", line 155, in __init__
    self.nodelist = self.compile_nodelist()
  File "C:\Users\tarlo\Desktop\Code\DJANGO\instamiligram\venv\lib\site-packages\django\template\base.py", line 193, in compile_nodelist
    return parser.parse()
  File "C:\Users\tarlo\Desktop\Code\DJANGO\instamiligram\venv\lib\site-packages\django\template\base.py", line 478, in parse
    raise self.error(token, e)
  File "C:\Users\tarlo\Desktop\Code\DJANGO\instamiligram\venv\lib\site-packages\django\template\base.py", line 476, in parse
    compiled_result = compile_func(self, token)
  File "C:\Users\tarlo\Desktop\Code\DJANGO\instamiligram\venv\lib\site-packages\django\template\loader_tags.py", line 278, in do_extends
    nodelist = parser.parse()
  File "C:\Users\tarlo\Desktop\Code\DJANGO\instamiligram\venv\lib\site-packages\django\template\base.py", line 472, in parse
    self.invalid_block_tag(token, command, parse_until)
  File "C:\Users\tarlo\Desktop\Code\DJANGO\instamiligram\venv\lib\site-packages\django\template\base.py", line 531, in invalid_block_tag
    raise self.error(
django.template.exceptions.TemplateSyntaxError: Invalid block tag on line 3: 'get_user_posts'. Did you forget to register or load this tag?
2021-11-08 19:47:54,383 django.request ERROR    Internal Server Error: /profile/koji
Traceback (most recent call last):
  File "C:\Users\tarlo\Desktop\Code\DJANGO\instamiligram\venv\lib\site-packages\django\template\base.py", line 470, in parse
    compile_func = self.tags[command]
KeyError: 'get_user_posts'

During handling of the above exception, another exception occurred:

Traceback (most recent call last):
  File "C:\Users\tarlo\Desktop\Code\DJANGO\instamiligram\venv\lib\site-packages\django\core\handlers\exception.py", line 47, in inner
    response = get_response(request)
  File "C:\Users\tarlo\Desktop\Code\DJANGO\instamiligram\venv\lib\site-packages\django\core\handlers\base.py", line 181, in _get_response
    response = wrapped_callback(request, *callback_args, **callback_kwargs)
  File "C:\Users\tarlo\Desktop\Code\DJANGO\instamiligram\venv\lib\site-packages\django\views\generic\base.py", line 70, in view
    return self.dispatch(request, *args, **kwargs)
  File "C:\Users\tarlo\Desktop\Code\DJANGO\instamiligram\venv\lib\site-packages\django\views\generic\base.py", line 98, in dispatch
    return handler(request, *args, **kwargs)
  File "C:\Users\tarlo\Desktop\Code\DJANGO\instamiligram\users\views.py", line 108, in get
    return render(request, "users/profile.html", {"user": User.objects.filter(username=username).first()})
  File "C:\Users\tarlo\Desktop\Code\DJANGO\instamiligram\venv\lib\site-packages\django\shortcuts.py", line 19, in render
    content = loader.render_to_string(template_name, context, request, using=using)
  File "C:\Users\tarlo\Desktop\Code\DJANGO\instamiligram\venv\lib\site-packages\django\template\loader.py", line 61, in render_to_string
    template = get_template(template_name, using=using)
  File "C:\Users\tarlo\Desktop\Code\DJANGO\instamiligram\venv\lib\site-packages\django\template\loader.py", line 15, in get_template
    return engine.get_template(template_name)
  File "C:\Users\tarlo\Desktop\Code\DJANGO\instamiligram\venv\lib\site-packages\django\template\backends\django.py", line 34, in get_template
    return Template(self.engine.get_template(template_name), self)
  File "C:\Users\tarlo\Desktop\Code\DJANGO\instamiligram\venv\lib\site-packages\django\template\engine.py", line 143, in get_template
    template, origin = self.find_template(template_name)
  File "C:\Users\tarlo\Desktop\Code\DJANGO\instamiligram\venv\lib\site-packages\django\template\engine.py", line 125, in find_template
    template = loader.get_template(name, skip=skip)
  File "C:\Users\tarlo\Desktop\Code\DJANGO\instamiligram\venv\lib\site-packages\django\template\loaders\base.py", line 29, in get_template
    return Template(
  File "C:\Users\tarlo\Desktop\Code\DJANGO\instamiligram\venv\lib\site-packages\django\template\base.py", line 155, in __init__
    self.nodelist = self.compile_nodelist()
  File "C:\Users\tarlo\Desktop\Code\DJANGO\instamiligram\venv\lib\site-packages\django\template\base.py", line 193, in compile_nodelist
    return parser.parse()
  File "C:\Users\tarlo\Desktop\Code\DJANGO\instamiligram\venv\lib\site-packages\django\template\base.py", line 478, in parse
    raise self.error(token, e)
  File "C:\Users\tarlo\Desktop\Code\DJANGO\instamiligram\venv\lib\site-packages\django\template\base.py", line 476, in parse
    compiled_result = compile_func(self, token)
  File "C:\Users\tarlo\Desktop\Code\DJANGO\instamiligram\venv\lib\site-packages\django\template\loader_tags.py", line 278, in do_extends
    nodelist = parser.parse()
  File "C:\Users\tarlo\Desktop\Code\DJANGO\instamiligram\venv\lib\site-packages\django\template\base.py", line 472, in parse
    self.invalid_block_tag(token, command, parse_until)
  File "C:\Users\tarlo\Desktop\Code\DJANGO\instamiligram\venv\lib\site-packages\django\template\base.py", line 531, in invalid_block_tag
    raise self.error(
django.template.exceptions.TemplateSyntaxError: Invalid block tag on line 3: 'get_user_posts'. Did you forget to register or load this tag?
2021-11-08 19:47:54,648 django.request ERROR    Internal Server Error: /profile/koji
Traceback (most recent call last):
  File "C:\Users\tarlo\Desktop\Code\DJANGO\instamiligram\venv\lib\site-packages\django\template\base.py", line 470, in parse
    compile_func = self.tags[command]
KeyError: 'get_user_posts'

During handling of the above exception, another exception occurred:

Traceback (most recent call last):
  File "C:\Users\tarlo\Desktop\Code\DJANGO\instamiligram\venv\lib\site-packages\django\core\handlers\exception.py", line 47, in inner
    response = get_response(request)
  File "C:\Users\tarlo\Desktop\Code\DJANGO\instamiligram\venv\lib\site-packages\django\core\handlers\base.py", line 181, in _get_response
    response = wrapped_callback(request, *callback_args, **callback_kwargs)
  File "C:\Users\tarlo\Desktop\Code\DJANGO\instamiligram\venv\lib\site-packages\django\views\generic\base.py", line 70, in view
    return self.dispatch(request, *args, **kwargs)
  File "C:\Users\tarlo\Desktop\Code\DJANGO\instamiligram\venv\lib\site-packages\django\views\generic\base.py", line 98, in dispatch
    return handler(request, *args, **kwargs)
  File "C:\Users\tarlo\Desktop\Code\DJANGO\instamiligram\users\views.py", line 108, in get
    return render(request, "users/profile.html", {"user": User.objects.filter(username=username).first()})
  File "C:\Users\tarlo\Desktop\Code\DJANGO\instamiligram\venv\lib\site-packages\django\shortcuts.py", line 19, in render
    content = loader.render_to_string(template_name, context, request, using=using)
  File "C:\Users\tarlo\Desktop\Code\DJANGO\instamiligram\venv\lib\site-packages\django\template\loader.py", line 61, in render_to_string
    template = get_template(template_name, using=using)
  File "C:\Users\tarlo\Desktop\Code\DJANGO\instamiligram\venv\lib\site-packages\django\template\loader.py", line 15, in get_template
    return engine.get_template(template_name)
  File "C:\Users\tarlo\Desktop\Code\DJANGO\instamiligram\venv\lib\site-packages\django\template\backends\django.py", line 34, in get_template
    return Template(self.engine.get_template(template_name), self)
  File "C:\Users\tarlo\Desktop\Code\DJANGO\instamiligram\venv\lib\site-packages\django\template\engine.py", line 143, in get_template
    template, origin = self.find_template(template_name)
  File "C:\Users\tarlo\Desktop\Code\DJANGO\instamiligram\venv\lib\site-packages\django\template\engine.py", line 125, in find_template
    template = loader.get_template(name, skip=skip)
  File "C:\Users\tarlo\Desktop\Code\DJANGO\instamiligram\venv\lib\site-packages\django\template\loaders\base.py", line 29, in get_template
    return Template(
  File "C:\Users\tarlo\Desktop\Code\DJANGO\instamiligram\venv\lib\site-packages\django\template\base.py", line 155, in __init__
    self.nodelist = self.compile_nodelist()
  File "C:\Users\tarlo\Desktop\Code\DJANGO\instamiligram\venv\lib\site-packages\django\template\base.py", line 193, in compile_nodelist
    return parser.parse()
  File "C:\Users\tarlo\Desktop\Code\DJANGO\instamiligram\venv\lib\site-packages\django\template\base.py", line 478, in parse
    raise self.error(token, e)
  File "C:\Users\tarlo\Desktop\Code\DJANGO\instamiligram\venv\lib\site-packages\django\template\base.py", line 476, in parse
    compiled_result = compile_func(self, token)
  File "C:\Users\tarlo\Desktop\Code\DJANGO\instamiligram\venv\lib\site-packages\django\template\loader_tags.py", line 278, in do_extends
    nodelist = parser.parse()
  File "C:\Users\tarlo\Desktop\Code\DJANGO\instamiligram\venv\lib\site-packages\django\template\base.py", line 472, in parse
    self.invalid_block_tag(token, command, parse_until)
  File "C:\Users\tarlo\Desktop\Code\DJANGO\instamiligram\venv\lib\site-packages\django\template\base.py", line 531, in invalid_block_tag
    raise self.error(
django.template.exceptions.TemplateSyntaxError: Invalid block tag on line 3: 'get_user_posts'. Did you forget to register or load this tag?
2021-11-08 19:47:54,953 django.request ERROR    Internal Server Error: /profile/koji
Traceback (most recent call last):
  File "C:\Users\tarlo\Desktop\Code\DJANGO\instamiligram\venv\lib\site-packages\django\template\base.py", line 470, in parse
    compile_func = self.tags[command]
KeyError: 'get_user_posts'

During handling of the above exception, another exception occurred:

Traceback (most recent call last):
  File "C:\Users\tarlo\Desktop\Code\DJANGO\instamiligram\venv\lib\site-packages\django\core\handlers\exception.py", line 47, in inner
    response = get_response(request)
  File "C:\Users\tarlo\Desktop\Code\DJANGO\instamiligram\venv\lib\site-packages\django\core\handlers\base.py", line 181, in _get_response
    response = wrapped_callback(request, *callback_args, **callback_kwargs)
  File "C:\Users\tarlo\Desktop\Code\DJANGO\instamiligram\venv\lib\site-packages\django\views\generic\base.py", line 70, in view
    return self.dispatch(request, *args, **kwargs)
  File "C:\Users\tarlo\Desktop\Code\DJANGO\instamiligram\venv\lib\site-packages\django\views\generic\base.py", line 98, in dispatch
    return handler(request, *args, **kwargs)
  File "C:\Users\tarlo\Desktop\Code\DJANGO\instamiligram\users\views.py", line 108, in get
    return render(request, "users/profile.html", {"user": User.objects.filter(username=username).first()})
  File "C:\Users\tarlo\Desktop\Code\DJANGO\instamiligram\venv\lib\site-packages\django\shortcuts.py", line 19, in render
    content = loader.render_to_string(template_name, context, request, using=using)
  File "C:\Users\tarlo\Desktop\Code\DJANGO\instamiligram\venv\lib\site-packages\django\template\loader.py", line 61, in render_to_string
    template = get_template(template_name, using=using)
  File "C:\Users\tarlo\Desktop\Code\DJANGO\instamiligram\venv\lib\site-packages\django\template\loader.py", line 15, in get_template
    return engine.get_template(template_name)
  File "C:\Users\tarlo\Desktop\Code\DJANGO\instamiligram\venv\lib\site-packages\django\template\backends\django.py", line 34, in get_template
    return Template(self.engine.get_template(template_name), self)
  File "C:\Users\tarlo\Desktop\Code\DJANGO\instamiligram\venv\lib\site-packages\django\template\engine.py", line 143, in get_template
    template, origin = self.find_template(template_name)
  File "C:\Users\tarlo\Desktop\Code\DJANGO\instamiligram\venv\lib\site-packages\django\template\engine.py", line 125, in find_template
    template = loader.get_template(name, skip=skip)
  File "C:\Users\tarlo\Desktop\Code\DJANGO\instamiligram\venv\lib\site-packages\django\template\loaders\base.py", line 29, in get_template
    return Template(
  File "C:\Users\tarlo\Desktop\Code\DJANGO\instamiligram\venv\lib\site-packages\django\template\base.py", line 155, in __init__
    self.nodelist = self.compile_nodelist()
  File "C:\Users\tarlo\Desktop\Code\DJANGO\instamiligram\venv\lib\site-packages\django\template\base.py", line 193, in compile_nodelist
    return parser.parse()
  File "C:\Users\tarlo\Desktop\Code\DJANGO\instamiligram\venv\lib\site-packages\django\template\base.py", line 478, in parse
    raise self.error(token, e)
  File "C:\Users\tarlo\Desktop\Code\DJANGO\instamiligram\venv\lib\site-packages\django\template\base.py", line 476, in parse
    compiled_result = compile_func(self, token)
  File "C:\Users\tarlo\Desktop\Code\DJANGO\instamiligram\venv\lib\site-packages\django\template\loader_tags.py", line 278, in do_extends
    nodelist = parser.parse()
  File "C:\Users\tarlo\Desktop\Code\DJANGO\instamiligram\venv\lib\site-packages\django\template\base.py", line 472, in parse
    self.invalid_block_tag(token, command, parse_until)
  File "C:\Users\tarlo\Desktop\Code\DJANGO\instamiligram\venv\lib\site-packages\django\template\base.py", line 531, in invalid_block_tag
    raise self.error(
django.template.exceptions.TemplateSyntaxError: Invalid block tag on line 3: 'get_user_posts'. Did you forget to register or load this tag?
2021-11-08 19:47:55,215 django.request ERROR    Internal Server Error: /profile/koji
Traceback (most recent call last):
  File "C:\Users\tarlo\Desktop\Code\DJANGO\instamiligram\venv\lib\site-packages\django\template\base.py", line 470, in parse
    compile_func = self.tags[command]
KeyError: 'get_user_posts'

During handling of the above exception, another exception occurred:

Traceback (most recent call last):
  File "C:\Users\tarlo\Desktop\Code\DJANGO\instamiligram\venv\lib\site-packages\django\core\handlers\exception.py", line 47, in inner
    response = get_response(request)
  File "C:\Users\tarlo\Desktop\Code\DJANGO\instamiligram\venv\lib\site-packages\django\core\handlers\base.py", line 181, in _get_response
    response = wrapped_callback(request, *callback_args, **callback_kwargs)
  File "C:\Users\tarlo\Desktop\Code\DJANGO\instamiligram\venv\lib\site-packages\django\views\generic\base.py", line 70, in view
    return self.dispatch(request, *args, **kwargs)
  File "C:\Users\tarlo\Desktop\Code\DJANGO\instamiligram\venv\lib\site-packages\django\views\generic\base.py", line 98, in dispatch
    return handler(request, *args, **kwargs)
  File "C:\Users\tarlo\Desktop\Code\DJANGO\instamiligram\users\views.py", line 108, in get
    return render(request, "users/profile.html", {"user": User.objects.filter(username=username).first()})
  File "C:\Users\tarlo\Desktop\Code\DJANGO\instamiligram\venv\lib\site-packages\django\shortcuts.py", line 19, in render
    content = loader.render_to_string(template_name, context, request, using=using)
  File "C:\Users\tarlo\Desktop\Code\DJANGO\instamiligram\venv\lib\site-packages\django\template\loader.py", line 61, in render_to_string
    template = get_template(template_name, using=using)
  File "C:\Users\tarlo\Desktop\Code\DJANGO\instamiligram\venv\lib\site-packages\django\template\loader.py", line 15, in get_template
    return engine.get_template(template_name)
  File "C:\Users\tarlo\Desktop\Code\DJANGO\instamiligram\venv\lib\site-packages\django\template\backends\django.py", line 34, in get_template
    return Template(self.engine.get_template(template_name), self)
  File "C:\Users\tarlo\Desktop\Code\DJANGO\instamiligram\venv\lib\site-packages\django\template\engine.py", line 143, in get_template
    template, origin = self.find_template(template_name)
  File "C:\Users\tarlo\Desktop\Code\DJANGO\instamiligram\venv\lib\site-packages\django\template\engine.py", line 125, in find_template
    template = loader.get_template(name, skip=skip)
  File "C:\Users\tarlo\Desktop\Code\DJANGO\instamiligram\venv\lib\site-packages\django\template\loaders\base.py", line 29, in get_template
    return Template(
  File "C:\Users\tarlo\Desktop\Code\DJANGO\instamiligram\venv\lib\site-packages\django\template\base.py", line 155, in __init__
    self.nodelist = self.compile_nodelist()
  File "C:\Users\tarlo\Desktop\Code\DJANGO\instamiligram\venv\lib\site-packages\django\template\base.py", line 193, in compile_nodelist
    return parser.parse()
  File "C:\Users\tarlo\Desktop\Code\DJANGO\instamiligram\venv\lib\site-packages\django\template\base.py", line 478, in parse
    raise self.error(token, e)
  File "C:\Users\tarlo\Desktop\Code\DJANGO\instamiligram\venv\lib\site-packages\django\template\base.py", line 476, in parse
    compiled_result = compile_func(self, token)
  File "C:\Users\tarlo\Desktop\Code\DJANGO\instamiligram\venv\lib\site-packages\django\template\loader_tags.py", line 278, in do_extends
    nodelist = parser.parse()
  File "C:\Users\tarlo\Desktop\Code\DJANGO\instamiligram\venv\lib\site-packages\django\template\base.py", line 472, in parse
    self.invalid_block_tag(token, command, parse_until)
  File "C:\Users\tarlo\Desktop\Code\DJANGO\instamiligram\venv\lib\site-packages\django\template\base.py", line 531, in invalid_block_tag
    raise self.error(
django.template.exceptions.TemplateSyntaxError: Invalid block tag on line 3: 'get_user_posts'. Did you forget to register or load this tag?
2021-11-10 15:16:17,174 django.request WARNING  Not Found: /favicon.ico
2021-11-10 15:26:24,738 django.request WARNING  Not Found: /chat
2021-11-10 15:26:27,890 django.request ERROR    Internal Server Error: /chats/
Traceback (most recent call last):
  File "C:\Users\tarlo\Desktop\Code\DJANGO\instamiligram\venv\lib\site-packages\django\core\handlers\exception.py", line 47, in inner
    response = get_response(request)
  File "C:\Users\tarlo\Desktop\Code\DJANGO\instamiligram\venv\lib\site-packages\django\core\handlers\base.py", line 181, in _get_response
    response = wrapped_callback(request, *callback_args, **callback_kwargs)
  File "C:\Users\tarlo\Desktop\Code\DJANGO\instamiligram\venv\lib\site-packages\django\views\generic\base.py", line 70, in view
    return self.dispatch(request, *args, **kwargs)
  File "C:\Users\tarlo\Desktop\Code\DJANGO\instamiligram\venv\lib\site-packages\django\views\generic\base.py", line 98, in dispatch
    return handler(request, *args, **kwargs)
  File "C:\Users\tarlo\Desktop\Code\DJANGO\instamiligram\chat\views.py", line 12, in get
    return render(request, "chat/home.html", context={'user': u})
  File "C:\Users\tarlo\Desktop\Code\DJANGO\instamiligram\venv\lib\site-packages\django\shortcuts.py", line 19, in render
    content = loader.render_to_string(template_name, context, request, using=using)
  File "C:\Users\tarlo\Desktop\Code\DJANGO\instamiligram\venv\lib\site-packages\django\template\loader.py", line 61, in render_to_string
    template = get_template(template_name, using=using)
  File "C:\Users\tarlo\Desktop\Code\DJANGO\instamiligram\venv\lib\site-packages\django\template\loader.py", line 19, in get_template
    raise TemplateDoesNotExist(template_name, chain=chain)
django.template.exceptions.TemplateDoesNotExist: chat/home.html
2021-11-10 15:28:05,344 django.request ERROR    Internal Server Error: /chats/
Traceback (most recent call last):
  File "C:\Users\tarlo\Desktop\Code\DJANGO\instamiligram\venv\lib\site-packages\django\core\handlers\exception.py", line 47, in inner
    response = get_response(request)
  File "C:\Users\tarlo\Desktop\Code\DJANGO\instamiligram\venv\lib\site-packages\django\core\handlers\base.py", line 181, in _get_response
    response = wrapped_callback(request, *callback_args, **callback_kwargs)
  File "C:\Users\tarlo\Desktop\Code\DJANGO\instamiligram\venv\lib\site-packages\django\views\generic\base.py", line 70, in view
    return self.dispatch(request, *args, **kwargs)
  File "C:\Users\tarlo\Desktop\Code\DJANGO\instamiligram\venv\lib\site-packages\django\views\generic\base.py", line 98, in dispatch
    return handler(request, *args, **kwargs)
  File "C:\Users\tarlo\Desktop\Code\DJANGO\instamiligram\chat\views.py", line 12, in get
    return render(request, "chat/chat-home.html", context={'user': u})
  File "C:\Users\tarlo\Desktop\Code\DJANGO\instamiligram\venv\lib\site-packages\django\shortcuts.py", line 19, in render
    content = loader.render_to_string(template_name, context, request, using=using)
  File "C:\Users\tarlo\Desktop\Code\DJANGO\instamiligram\venv\lib\site-packages\django\template\loader.py", line 61, in render_to_string
    template = get_template(template_name, using=using)
  File "C:\Users\tarlo\Desktop\Code\DJANGO\instamiligram\venv\lib\site-packages\django\template\loader.py", line 19, in get_template
    raise TemplateDoesNotExist(template_name, chain=chain)
django.template.exceptions.TemplateDoesNotExist: chat/chat-home.html
2021-11-10 15:28:19,453 django.request ERROR    Internal Server Error: /chats/
Traceback (most recent call last):
  File "C:\Users\tarlo\Desktop\Code\DJANGO\instamiligram\venv\lib\site-packages\django\core\handlers\exception.py", line 47, in inner
    response = get_response(request)
  File "C:\Users\tarlo\Desktop\Code\DJANGO\instamiligram\venv\lib\site-packages\django\core\handlers\base.py", line 181, in _get_response
    response = wrapped_callback(request, *callback_args, **callback_kwargs)
  File "C:\Users\tarlo\Desktop\Code\DJANGO\instamiligram\venv\lib\site-packages\django\views\generic\base.py", line 70, in view
    return self.dispatch(request, *args, **kwargs)
  File "C:\Users\tarlo\Desktop\Code\DJANGO\instamiligram\venv\lib\site-packages\django\views\generic\base.py", line 98, in dispatch
    return handler(request, *args, **kwargs)
  File "C:\Users\tarlo\Desktop\Code\DJANGO\instamiligram\chat\views.py", line 12, in get
    return render(request, "chats/chat-home.html", context={'user': u})
  File "C:\Users\tarlo\Desktop\Code\DJANGO\instamiligram\venv\lib\site-packages\django\shortcuts.py", line 19, in render
    content = loader.render_to_string(template_name, context, request, using=using)
  File "C:\Users\tarlo\Desktop\Code\DJANGO\instamiligram\venv\lib\site-packages\django\template\loader.py", line 61, in render_to_string
    template = get_template(template_name, using=using)
  File "C:\Users\tarlo\Desktop\Code\DJANGO\instamiligram\venv\lib\site-packages\django\template\loader.py", line 19, in get_template
    raise TemplateDoesNotExist(template_name, chain=chain)
django.template.exceptions.TemplateDoesNotExist: chats/chat-home.html
2021-11-10 15:33:02,526 django.request ERROR    Internal Server Error: /chats/
Traceback (most recent call last):
  File "C:\Users\tarlo\Desktop\Code\DJANGO\instamiligram\venv\lib\site-packages\django\core\handlers\exception.py", line 47, in inner
    response = get_response(request)
  File "C:\Users\tarlo\Desktop\Code\DJANGO\instamiligram\venv\lib\site-packages\django\core\handlers\base.py", line 181, in _get_response
    response = wrapped_callback(request, *callback_args, **callback_kwargs)
  File "C:\Users\tarlo\Desktop\Code\DJANGO\instamiligram\venv\lib\site-packages\django\views\generic\base.py", line 70, in view
    return self.dispatch(request, *args, **kwargs)
  File "C:\Users\tarlo\Desktop\Code\DJANGO\instamiligram\venv\lib\site-packages\django\views\generic\base.py", line 98, in dispatch
    return handler(request, *args, **kwargs)
  File "C:\Users\tarlo\Desktop\Code\DJANGO\instamiligram\chat\views.py", line 12, in get
    return render(request, "chats/chat-home.html", context={'user': u})
  File "C:\Users\tarlo\Desktop\Code\DJANGO\instamiligram\venv\lib\site-packages\django\shortcuts.py", line 19, in render
    content = loader.render_to_string(template_name, context, request, using=using)
  File "C:\Users\tarlo\Desktop\Code\DJANGO\instamiligram\venv\lib\site-packages\django\template\loader.py", line 61, in render_to_string
    template = get_template(template_name, using=using)
  File "C:\Users\tarlo\Desktop\Code\DJANGO\instamiligram\venv\lib\site-packages\django\template\loader.py", line 15, in get_template
    return engine.get_template(template_name)
  File "C:\Users\tarlo\Desktop\Code\DJANGO\instamiligram\venv\lib\site-packages\django\template\backends\django.py", line 34, in get_template
    return Template(self.engine.get_template(template_name), self)
  File "C:\Users\tarlo\Desktop\Code\DJANGO\instamiligram\venv\lib\site-packages\django\template\engine.py", line 143, in get_template
    template, origin = self.find_template(template_name)
  File "C:\Users\tarlo\Desktop\Code\DJANGO\instamiligram\venv\lib\site-packages\django\template\engine.py", line 125, in find_template
    template = loader.get_template(name, skip=skip)
  File "C:\Users\tarlo\Desktop\Code\DJANGO\instamiligram\venv\lib\site-packages\django\template\loaders\base.py", line 29, in get_template
    return Template(
  File "C:\Users\tarlo\Desktop\Code\DJANGO\instamiligram\venv\lib\site-packages\django\template\base.py", line 155, in __init__
    self.nodelist = self.compile_nodelist()
  File "C:\Users\tarlo\Desktop\Code\DJANGO\instamiligram\venv\lib\site-packages\django\template\base.py", line 193, in compile_nodelist
    return parser.parse()
  File "C:\Users\tarlo\Desktop\Code\DJANGO\instamiligram\venv\lib\site-packages\django\template\base.py", line 478, in parse
    raise self.error(token, e)
  File "C:\Users\tarlo\Desktop\Code\DJANGO\instamiligram\venv\lib\site-packages\django\template\base.py", line 476, in parse
    compiled_result = compile_func(self, token)
  File "C:\Users\tarlo\Desktop\Code\DJANGO\instamiligram\venv\lib\site-packages\django\template\loader_tags.py", line 278, in do_extends
    nodelist = parser.parse()
  File "C:\Users\tarlo\Desktop\Code\DJANGO\instamiligram\venv\lib\site-packages\django\template\base.py", line 478, in parse
    raise self.error(token, e)
  File "C:\Users\tarlo\Desktop\Code\DJANGO\instamiligram\venv\lib\site-packages\django\template\base.py", line 476, in parse
    compiled_result = compile_func(self, token)
  File "C:\Users\tarlo\Desktop\Code\DJANGO\instamiligram\venv\lib\site-packages\django\template\loader_tags.py", line 216, in do_block
    nodelist = parser.parse(('endblock',))
  File "C:\Users\tarlo\Desktop\Code\DJANGO\instamiligram\venv\lib\site-packages\django\template\base.py", line 478, in parse
    raise self.error(token, e)
  File "C:\Users\tarlo\Desktop\Code\DJANGO\instamiligram\venv\lib\site-packages\django\template\base.py", line 476, in parse
    compiled_result = compile_func(self, token)
  File "C:\Users\tarlo\Desktop\Code\DJANGO\instamiligram\venv\lib\site-packages\django\template\defaulttags.py", line 813, in do_for
    sequence = parser.compile_filter(bits[in_index + 1])
  File "C:\Users\tarlo\Desktop\Code\DJANGO\instamiligram\venv\lib\site-packages\django\template\base.py", line 563, in compile_filter
    return FilterExpression(token, self)
  File "C:\Users\tarlo\Desktop\Code\DJANGO\instamiligram\venv\lib\site-packages\django\template\base.py", line 662, in __init__
    raise TemplateSyntaxError("Could not parse the remainder: '%s' "
django.template.exceptions.TemplateSyntaxError: Could not parse the remainder: '(5)' from 'range(5)'
2021-11-10 15:33:20,247 django.request ERROR    Internal Server Error: /chats/
Traceback (most recent call last):
  File "C:\Users\tarlo\Desktop\Code\DJANGO\instamiligram\venv\lib\site-packages\django\core\handlers\exception.py", line 47, in inner
    response = get_response(request)
  File "C:\Users\tarlo\Desktop\Code\DJANGO\instamiligram\venv\lib\site-packages\django\core\handlers\base.py", line 181, in _get_response
    response = wrapped_callback(request, *callback_args, **callback_kwargs)
  File "C:\Users\tarlo\Desktop\Code\DJANGO\instamiligram\venv\lib\site-packages\django\views\generic\base.py", line 70, in view
    return self.dispatch(request, *args, **kwargs)
  File "C:\Users\tarlo\Desktop\Code\DJANGO\instamiligram\venv\lib\site-packages\django\views\generic\base.py", line 98, in dispatch
    return handler(request, *args, **kwargs)
  File "C:\Users\tarlo\Desktop\Code\DJANGO\instamiligram\chat\views.py", line 12, in get
    return render(request, "chats/chat-home.html", context={'user': u})
  File "C:\Users\tarlo\Desktop\Code\DJANGO\instamiligram\venv\lib\site-packages\django\shortcuts.py", line 19, in render
    content = loader.render_to_string(template_name, context, request, using=using)
  File "C:\Users\tarlo\Desktop\Code\DJANGO\instamiligram\venv\lib\site-packages\django\template\loader.py", line 61, in render_to_string
    template = get_template(template_name, using=using)
  File "C:\Users\tarlo\Desktop\Code\DJANGO\instamiligram\venv\lib\site-packages\django\template\loader.py", line 15, in get_template
    return engine.get_template(template_name)
  File "C:\Users\tarlo\Desktop\Code\DJANGO\instamiligram\venv\lib\site-packages\django\template\backends\django.py", line 34, in get_template
    return Template(self.engine.get_template(template_name), self)
  File "C:\Users\tarlo\Desktop\Code\DJANGO\instamiligram\venv\lib\site-packages\django\template\engine.py", line 143, in get_template
    template, origin = self.find_template(template_name)
  File "C:\Users\tarlo\Desktop\Code\DJANGO\instamiligram\venv\lib\site-packages\django\template\engine.py", line 125, in find_template
    template = loader.get_template(name, skip=skip)
  File "C:\Users\tarlo\Desktop\Code\DJANGO\instamiligram\venv\lib\site-packages\django\template\loaders\base.py", line 29, in get_template
    return Template(
  File "C:\Users\tarlo\Desktop\Code\DJANGO\instamiligram\venv\lib\site-packages\django\template\base.py", line 155, in __init__
    self.nodelist = self.compile_nodelist()
  File "C:\Users\tarlo\Desktop\Code\DJANGO\instamiligram\venv\lib\site-packages\django\template\base.py", line 193, in compile_nodelist
    return parser.parse()
  File "C:\Users\tarlo\Desktop\Code\DJANGO\instamiligram\venv\lib\site-packages\django\template\base.py", line 478, in parse
    raise self.error(token, e)
  File "C:\Users\tarlo\Desktop\Code\DJANGO\instamiligram\venv\lib\site-packages\django\template\base.py", line 476, in parse
    compiled_result = compile_func(self, token)
  File "C:\Users\tarlo\Desktop\Code\DJANGO\instamiligram\venv\lib\site-packages\django\template\loader_tags.py", line 278, in do_extends
    nodelist = parser.parse()
  File "C:\Users\tarlo\Desktop\Code\DJANGO\instamiligram\venv\lib\site-packages\django\template\base.py", line 478, in parse
    raise self.error(token, e)
  File "C:\Users\tarlo\Desktop\Code\DJANGO\instamiligram\venv\lib\site-packages\django\template\base.py", line 476, in parse
    compiled_result = compile_func(self, token)
  File "C:\Users\tarlo\Desktop\Code\DJANGO\instamiligram\venv\lib\site-packages\django\template\loader_tags.py", line 216, in do_block
    nodelist = parser.parse(('endblock',))
  File "C:\Users\tarlo\Desktop\Code\DJANGO\instamiligram\venv\lib\site-packages\django\template\base.py", line 478, in parse
    raise self.error(token, e)
  File "C:\Users\tarlo\Desktop\Code\DJANGO\instamiligram\venv\lib\site-packages\django\template\base.py", line 476, in parse
    compiled_result = compile_func(self, token)
  File "C:\Users\tarlo\Desktop\Code\DJANGO\instamiligram\venv\lib\site-packages\django\template\defaulttags.py", line 813, in do_for
    sequence = parser.compile_filter(bits[in_index + 1])
  File "C:\Users\tarlo\Desktop\Code\DJANGO\instamiligram\venv\lib\site-packages\django\template\base.py", line 563, in compile_filter
    return FilterExpression(token, self)
  File "C:\Users\tarlo\Desktop\Code\DJANGO\instamiligram\venv\lib\site-packages\django\template\base.py", line 662, in __init__
    raise TemplateSyntaxError("Could not parse the remainder: '%s' "
django.template.exceptions.TemplateSyntaxError: Could not parse the remainder: '[1,2,3,]' from '[1,2,3,]'
2021-11-10 15:33:42,148 django.request ERROR    Internal Server Error: /chats/
Traceback (most recent call last):
  File "C:\Users\tarlo\Desktop\Code\DJANGO\instamiligram\venv\lib\site-packages\django\core\handlers\exception.py", line 47, in inner
    response = get_response(request)
  File "C:\Users\tarlo\Desktop\Code\DJANGO\instamiligram\venv\lib\site-packages\django\core\handlers\base.py", line 181, in _get_response
    response = wrapped_callback(request, *callback_args, **callback_kwargs)
  File "C:\Users\tarlo\Desktop\Code\DJANGO\instamiligram\venv\lib\site-packages\django\views\generic\base.py", line 70, in view
    return self.dispatch(request, *args, **kwargs)
  File "C:\Users\tarlo\Desktop\Code\DJANGO\instamiligram\venv\lib\site-packages\django\views\generic\base.py", line 98, in dispatch
    return handler(request, *args, **kwargs)
  File "C:\Users\tarlo\Desktop\Code\DJANGO\instamiligram\chat\views.py", line 12, in get
    return render(request, "chats/chat-home.html", context={'user': u, 'range': range(5)})
  File "C:\Users\tarlo\Desktop\Code\DJANGO\instamiligram\venv\lib\site-packages\django\shortcuts.py", line 19, in render
    content = loader.render_to_string(template_name, context, request, using=using)
  File "C:\Users\tarlo\Desktop\Code\DJANGO\instamiligram\venv\lib\site-packages\django\template\loader.py", line 61, in render_to_string
    template = get_template(template_name, using=using)
  File "C:\Users\tarlo\Desktop\Code\DJANGO\instamiligram\venv\lib\site-packages\django\template\loader.py", line 15, in get_template
    return engine.get_template(template_name)
  File "C:\Users\tarlo\Desktop\Code\DJANGO\instamiligram\venv\lib\site-packages\django\template\backends\django.py", line 34, in get_template
    return Template(self.engine.get_template(template_name), self)
  File "C:\Users\tarlo\Desktop\Code\DJANGO\instamiligram\venv\lib\site-packages\django\template\engine.py", line 143, in get_template
    template, origin = self.find_template(template_name)
  File "C:\Users\tarlo\Desktop\Code\DJANGO\instamiligram\venv\lib\site-packages\django\template\engine.py", line 125, in find_template
    template = loader.get_template(name, skip=skip)
  File "C:\Users\tarlo\Desktop\Code\DJANGO\instamiligram\venv\lib\site-packages\django\template\loaders\base.py", line 29, in get_template
    return Template(
  File "C:\Users\tarlo\Desktop\Code\DJANGO\instamiligram\venv\lib\site-packages\django\template\base.py", line 155, in __init__
    self.nodelist = self.compile_nodelist()
  File "C:\Users\tarlo\Desktop\Code\DJANGO\instamiligram\venv\lib\site-packages\django\template\base.py", line 193, in compile_nodelist
    return parser.parse()
  File "C:\Users\tarlo\Desktop\Code\DJANGO\instamiligram\venv\lib\site-packages\django\template\base.py", line 478, in parse
    raise self.error(token, e)
  File "C:\Users\tarlo\Desktop\Code\DJANGO\instamiligram\venv\lib\site-packages\django\template\base.py", line 476, in parse
    compiled_result = compile_func(self, token)
  File "C:\Users\tarlo\Desktop\Code\DJANGO\instamiligram\venv\lib\site-packages\django\template\loader_tags.py", line 278, in do_extends
    nodelist = parser.parse()
  File "C:\Users\tarlo\Desktop\Code\DJANGO\instamiligram\venv\lib\site-packages\django\template\base.py", line 478, in parse
    raise self.error(token, e)
  File "C:\Users\tarlo\Desktop\Code\DJANGO\instamiligram\venv\lib\site-packages\django\template\base.py", line 476, in parse
    compiled_result = compile_func(self, token)
  File "C:\Users\tarlo\Desktop\Code\DJANGO\instamiligram\venv\lib\site-packages\django\template\loader_tags.py", line 216, in do_block
    nodelist = parser.parse(('endblock',))
  File "C:\Users\tarlo\Desktop\Code\DJANGO\instamiligram\venv\lib\site-packages\django\template\base.py", line 478, in parse
    raise self.error(token, e)
  File "C:\Users\tarlo\Desktop\Code\DJANGO\instamiligram\venv\lib\site-packages\django\template\base.py", line 476, in parse
    compiled_result = compile_func(self, token)
  File "C:\Users\tarlo\Desktop\Code\DJANGO\instamiligram\venv\lib\site-packages\django\template\defaulttags.py", line 813, in do_for
    sequence = parser.compile_filter(bits[in_index + 1])
  File "C:\Users\tarlo\Desktop\Code\DJANGO\instamiligram\venv\lib\site-packages\django\template\base.py", line 563, in compile_filter
    return FilterExpression(token, self)
  File "C:\Users\tarlo\Desktop\Code\DJANGO\instamiligram\venv\lib\site-packages\django\template\base.py", line 662, in __init__
    raise TemplateSyntaxError("Could not parse the remainder: '%s' "
django.template.exceptions.TemplateSyntaxError: Could not parse the remainder: '{{range}}' from '{{range}}'
2021-11-10 22:10:06,782 django.request WARNING  Not Found: /favicon.ico
2021-11-10 22:10:22,293 django.request ERROR    Internal Server Error: /login/
Traceback (most recent call last):
  File "C:\Users\tarlo\AppData\Local\Programs\Python\Python39\lib\site-packages\django\core\handlers\exception.py", line 47, in inner
    response = get_response(request)
  File "C:\Users\tarlo\AppData\Local\Programs\Python\Python39\lib\site-packages\django\core\handlers\base.py", line 181, in _get_response
    response = wrapped_callback(request, *callback_args, **callback_kwargs)
  File "C:\Users\tarlo\AppData\Local\Programs\Python\Python39\lib\site-packages\django\views\generic\base.py", line 70, in view
    return self.dispatch(request, *args, **kwargs)
  File "C:\Users\tarlo\AppData\Local\Programs\Python\Python39\lib\site-packages\django\views\generic\base.py", line 98, in dispatch
    return handler(request, *args, **kwargs)
  File "C:\Users\tarlo\Desktop\Code\Python\instamiligram\users\views.py", line 37, in post
    login(request, user)
  File "C:\Users\tarlo\AppData\Local\Programs\Python\Python39\lib\site-packages\django\contrib\auth\__init__.py", line 135, in login
    user_logged_in.send(sender=user.__class__, request=request, user=user)
  File "C:\Users\tarlo\AppData\Local\Programs\Python\Python39\lib\site-packages\django\dispatch\dispatcher.py", line 180, in send
    return [
  File "C:\Users\tarlo\AppData\Local\Programs\Python\Python39\lib\site-packages\django\dispatch\dispatcher.py", line 181, in <listcomp>
    (receiver, receiver(signal=self, sender=sender, **named))
  File "C:\Users\tarlo\AppData\Local\Programs\Python\Python39\lib\site-packages\django\contrib\auth\models.py", line 22, in update_last_login
    user.save(update_fields=['last_login'])
  File "C:\Users\tarlo\AppData\Local\Programs\Python\Python39\lib\site-packages\django\contrib\auth\base_user.py", line 67, in save
    super().save(*args, **kwargs)
  File "C:\Users\tarlo\AppData\Local\Programs\Python\Python39\lib\site-packages\django\db\models\base.py", line 726, in save
    self.save_base(using=using, force_insert=force_insert,
  File "C:\Users\tarlo\AppData\Local\Programs\Python\Python39\lib\site-packages\django\db\models\base.py", line 774, in save_base
    post_save.send(
  File "C:\Users\tarlo\AppData\Local\Programs\Python\Python39\lib\site-packages\django\dispatch\dispatcher.py", line 180, in send
    return [
  File "C:\Users\tarlo\AppData\Local\Programs\Python\Python39\lib\site-packages\django\dispatch\dispatcher.py", line 181, in <listcomp>
    (receiver, receiver(signal=self, sender=sender, **named))
  File "C:\Users\tarlo\Desktop\Code\Python\instamiligram\users\signals.py", line 15, in save_profile
    instance.profile.save()
  File "C:\Users\tarlo\Desktop\Code\Python\instamiligram\users\models.py", line 26, in save
    img = Image.open(self.image.path)
  File "C:\Users\tarlo\AppData\Local\Programs\Python\Python39\lib\site-packages\PIL\Image.py", line 2975, in open
    fp = builtins.open(filename, "rb")
FileNotFoundError: [Errno 2] No such file or directory: 'C:\\Users\\tarlo\\Desktop\\Code\\Python\\instamiligram\\media\\profile_pics\\1_L3q3XCs.jpg'
2021-11-11 22:13:51,219 django.request WARNING  Not Found: /favicon.ico
2021-11-11 22:13:54,761 django.request ERROR    Internal Server Error: /chats/
Traceback (most recent call last):
  File "C:\Users\tarlo\AppData\Local\Programs\Python\Python39\lib\site-packages\django\core\handlers\exception.py", line 47, in inner
    response = get_response(request)
  File "C:\Users\tarlo\AppData\Local\Programs\Python\Python39\lib\site-packages\django\core\handlers\base.py", line 181, in _get_response
    response = wrapped_callback(request, *callback_args, **callback_kwargs)
  File "C:\Users\tarlo\AppData\Local\Programs\Python\Python39\lib\site-packages\django\views\generic\base.py", line 70, in view
    return self.dispatch(request, *args, **kwargs)
  File "C:\Users\tarlo\AppData\Local\Programs\Python\Python39\lib\site-packages\django\views\generic\base.py", line 98, in dispatch
    return handler(request, *args, **kwargs)
  File "C:\Users\tarlo\Desktop\Code\Python\instamiligram\chat\views.py", line 12, in get
    return render(
  File "C:\Users\tarlo\AppData\Local\Programs\Python\Python39\lib\site-packages\django\shortcuts.py", line 19, in render
    content = loader.render_to_string(template_name, context, request, using=using)
  File "C:\Users\tarlo\AppData\Local\Programs\Python\Python39\lib\site-packages\django\template\loader.py", line 61, in render_to_string
    template = get_template(template_name, using=using)
  File "C:\Users\tarlo\AppData\Local\Programs\Python\Python39\lib\site-packages\django\template\loader.py", line 19, in get_template
    raise TemplateDoesNotExist(template_name, chain=chain)
django.template.exceptions.TemplateDoesNotExist: chat/chat-home.html
2021-11-11 22:14:38,223 django.request ERROR    Internal Server Error: /chats/
Traceback (most recent call last):
  File "C:\Users\tarlo\AppData\Local\Programs\Python\Python39\lib\site-packages\django\db\backends\utils.py", line 84, in _execute
    return self.cursor.execute(sql, params)
psycopg2.errors.UndefinedTable: ОШИБКА:  отношение "chat_message" не существует
LINE 1: ...ssage"."sended_at", "chat_message"."content" FROM "chat_mess...
                                                             ^


The above exception was the direct cause of the following exception:

Traceback (most recent call last):
  File "C:\Users\tarlo\AppData\Local\Programs\Python\Python39\lib\site-packages\django\core\handlers\exception.py", line 47, in inner
    response = get_response(request)
  File "C:\Users\tarlo\AppData\Local\Programs\Python\Python39\lib\site-packages\django\core\handlers\base.py", line 181, in _get_response
    response = wrapped_callback(request, *callback_args, **callback_kwargs)
  File "C:\Users\tarlo\AppData\Local\Programs\Python\Python39\lib\site-packages\django\views\generic\base.py", line 70, in view
    return self.dispatch(request, *args, **kwargs)
  File "C:\Users\tarlo\AppData\Local\Programs\Python\Python39\lib\site-packages\django\views\generic\base.py", line 98, in dispatch
    return handler(request, *args, **kwargs)
  File "C:\Users\tarlo\Desktop\Code\Python\instamiligram\chat\views.py", line 12, in get
    return render(
  File "C:\Users\tarlo\AppData\Local\Programs\Python\Python39\lib\site-packages\django\shortcuts.py", line 19, in render
    content = loader.render_to_string(template_name, context, request, using=using)
  File "C:\Users\tarlo\AppData\Local\Programs\Python\Python39\lib\site-packages\django\template\loader.py", line 62, in render_to_string
    return template.render(context, request)
  File "C:\Users\tarlo\AppData\Local\Programs\Python\Python39\lib\site-packages\django\template\backends\django.py", line 61, in render
    return self.template.render(context)
  File "C:\Users\tarlo\AppData\Local\Programs\Python\Python39\lib\site-packages\django\template\base.py", line 170, in render
    return self._render(context)
  File "C:\Users\tarlo\AppData\Local\Programs\Python\Python39\lib\site-packages\django\template\base.py", line 162, in _render
    return self.nodelist.render(context)
  File "C:\Users\tarlo\AppData\Local\Programs\Python\Python39\lib\site-packages\django\template\base.py", line 938, in render
    bit = node.render_annotated(context)
  File "C:\Users\tarlo\AppData\Local\Programs\Python\Python39\lib\site-packages\django\template\base.py", line 905, in render_annotated
    return self.render(context)
  File "C:\Users\tarlo\AppData\Local\Programs\Python\Python39\lib\site-packages\django\template\loader_tags.py", line 150, in render
    return compiled_parent._render(context)
  File "C:\Users\tarlo\AppData\Local\Programs\Python\Python39\lib\site-packages\django\template\base.py", line 162, in _render
    return self.nodelist.render(context)
  File "C:\Users\tarlo\AppData\Local\Programs\Python\Python39\lib\site-packages\django\template\base.py", line 938, in render
    bit = node.render_annotated(context)
  File "C:\Users\tarlo\AppData\Local\Programs\Python\Python39\lib\site-packages\django\template\base.py", line 905, in render_annotated
    return self.render(context)
  File "C:\Users\tarlo\AppData\Local\Programs\Python\Python39\lib\site-packages\django\template\defaulttags.py", line 311, in render
    if match:
  File "C:\Users\tarlo\AppData\Local\Programs\Python\Python39\lib\site-packages\django\db\models\query.py", line 284, in __bool__
    self._fetch_all()
  File "C:\Users\tarlo\AppData\Local\Programs\Python\Python39\lib\site-packages\django\db\models\query.py", line 1324, in _fetch_all
    self._result_cache = list(self._iterable_class(self))
  File "C:\Users\tarlo\AppData\Local\Programs\Python\Python39\lib\site-packages\django\db\models\query.py", line 51, in __iter__
    results = compiler.execute_sql(chunked_fetch=self.chunked_fetch, chunk_size=self.chunk_size)
  File "C:\Users\tarlo\AppData\Local\Programs\Python\Python39\lib\site-packages\django\db\models\sql\compiler.py", line 1175, in execute_sql
    cursor.execute(sql, params)
  File "C:\Users\tarlo\AppData\Local\Programs\Python\Python39\lib\site-packages\django\db\backends\utils.py", line 98, in execute
    return super().execute(sql, params)
  File "C:\Users\tarlo\AppData\Local\Programs\Python\Python39\lib\site-packages\django\db\backends\utils.py", line 66, in execute
    return self._execute_with_wrappers(sql, params, many=False, executor=self._execute)
  File "C:\Users\tarlo\AppData\Local\Programs\Python\Python39\lib\site-packages\django\db\backends\utils.py", line 75, in _execute_with_wrappers
    return executor(sql, params, many, context)
  File "C:\Users\tarlo\AppData\Local\Programs\Python\Python39\lib\site-packages\django\db\backends\utils.py", line 84, in _execute
    return self.cursor.execute(sql, params)
  File "C:\Users\tarlo\AppData\Local\Programs\Python\Python39\lib\site-packages\django\db\utils.py", line 90, in __exit__
    raise dj_exc_value.with_traceback(traceback) from exc_value
  File "C:\Users\tarlo\AppData\Local\Programs\Python\Python39\lib\site-packages\django\db\backends\utils.py", line 84, in _execute
    return self.cursor.execute(sql, params)
django.db.utils.ProgrammingError: ОШИБКА:  отношение "chat_message" не существует
LINE 1: ...ssage"."sended_at", "chat_message"."content" FROM "chat_mess...
                                                             ^

2021-11-11 22:25:12,494 django.request ERROR    Internal Server Error: /chats/
Traceback (most recent call last):
  File "C:\Users\tarlo\AppData\Local\Programs\Python\Python39\lib\site-packages\django\template\base.py", line 766, in __init__
    self.literal = float(var)
ValueError: could not convert string to float: '_messages'

During handling of the above exception, another exception occurred:

Traceback (most recent call last):
  File "C:\Users\tarlo\AppData\Local\Programs\Python\Python39\lib\site-packages\django\template\base.py", line 782, in __init__
    self.literal = mark_safe(unescape_string_literal(var))
  File "C:\Users\tarlo\AppData\Local\Programs\Python\Python39\lib\site-packages\django\utils\functional.py", line 228, in wrapper
    return func(*args, **kwargs)
  File "C:\Users\tarlo\AppData\Local\Programs\Python\Python39\lib\site-packages\django\utils\text.py", line 392, in unescape_string_literal
    raise ValueError("Not a string literal: %r" % s)
ValueError: Not a string literal: '_messages'

During handling of the above exception, another exception occurred:

Traceback (most recent call last):
  File "C:\Users\tarlo\AppData\Local\Programs\Python\Python39\lib\site-packages\django\core\handlers\exception.py", line 47, in inner
    response = get_response(request)
  File "C:\Users\tarlo\AppData\Local\Programs\Python\Python39\lib\site-packages\django\core\handlers\base.py", line 181, in _get_response
    response = wrapped_callback(request, *callback_args, **callback_kwargs)
  File "C:\Users\tarlo\AppData\Local\Programs\Python\Python39\lib\site-packages\django\views\generic\base.py", line 70, in view
    return self.dispatch(request, *args, **kwargs)
  File "C:\Users\tarlo\AppData\Local\Programs\Python\Python39\lib\site-packages\django\views\generic\base.py", line 98, in dispatch
    return handler(request, *args, **kwargs)
  File "C:\Users\tarlo\Desktop\Code\Python\instamiligram\chat\views.py", line 12, in get
    return render(
  File "C:\Users\tarlo\AppData\Local\Programs\Python\Python39\lib\site-packages\django\shortcuts.py", line 19, in render
    content = loader.render_to_string(template_name, context, request, using=using)
  File "C:\Users\tarlo\AppData\Local\Programs\Python\Python39\lib\site-packages\django\template\loader.py", line 61, in render_to_string
    template = get_template(template_name, using=using)
  File "C:\Users\tarlo\AppData\Local\Programs\Python\Python39\lib\site-packages\django\template\loader.py", line 15, in get_template
    return engine.get_template(template_name)
  File "C:\Users\tarlo\AppData\Local\Programs\Python\Python39\lib\site-packages\django\template\backends\django.py", line 34, in get_template
    return Template(self.engine.get_template(template_name), self)
  File "C:\Users\tarlo\AppData\Local\Programs\Python\Python39\lib\site-packages\django\template\engine.py", line 143, in get_template
    template, origin = self.find_template(template_name)
  File "C:\Users\tarlo\AppData\Local\Programs\Python\Python39\lib\site-packages\django\template\engine.py", line 125, in find_template
    template = loader.get_template(name, skip=skip)
  File "C:\Users\tarlo\AppData\Local\Programs\Python\Python39\lib\site-packages\django\template\loaders\base.py", line 29, in get_template
    return Template(
  File "C:\Users\tarlo\AppData\Local\Programs\Python\Python39\lib\site-packages\django\template\base.py", line 155, in __init__
    self.nodelist = self.compile_nodelist()
  File "C:\Users\tarlo\AppData\Local\Programs\Python\Python39\lib\site-packages\django\template\base.py", line 193, in compile_nodelist
    return parser.parse()
  File "C:\Users\tarlo\AppData\Local\Programs\Python\Python39\lib\site-packages\django\template\base.py", line 478, in parse
    raise self.error(token, e)
  File "C:\Users\tarlo\AppData\Local\Programs\Python\Python39\lib\site-packages\django\template\base.py", line 476, in parse
    compiled_result = compile_func(self, token)
  File "C:\Users\tarlo\AppData\Local\Programs\Python\Python39\lib\site-packages\django\template\loader_tags.py", line 278, in do_extends
    nodelist = parser.parse()
  File "C:\Users\tarlo\AppData\Local\Programs\Python\Python39\lib\site-packages\django\template\base.py", line 478, in parse
    raise self.error(token, e)
  File "C:\Users\tarlo\AppData\Local\Programs\Python\Python39\lib\site-packages\django\template\base.py", line 476, in parse
    compiled_result = compile_func(self, token)
  File "C:\Users\tarlo\AppData\Local\Programs\Python\Python39\lib\site-packages\django\template\loader_tags.py", line 216, in do_block
    nodelist = parser.parse(('endblock',))
  File "C:\Users\tarlo\AppData\Local\Programs\Python\Python39\lib\site-packages\django\template\base.py", line 478, in parse
    raise self.error(token, e)
  File "C:\Users\tarlo\AppData\Local\Programs\Python\Python39\lib\site-packages\django\template\base.py", line 476, in parse
    compiled_result = compile_func(self, token)
  File "C:\Users\tarlo\AppData\Local\Programs\Python\Python39\lib\site-packages\django\template\defaulttags.py", line 813, in do_for
    sequence = parser.compile_filter(bits[in_index + 1])
  File "C:\Users\tarlo\AppData\Local\Programs\Python\Python39\lib\site-packages\django\template\base.py", line 563, in compile_filter
    return FilterExpression(token, self)
  File "C:\Users\tarlo\AppData\Local\Programs\Python\Python39\lib\site-packages\django\template\base.py", line 648, in __init__
    var_obj = Variable(var)
  File "C:\Users\tarlo\AppData\Local\Programs\Python\Python39\lib\site-packages\django\template\base.py", line 787, in __init__
    raise TemplateSyntaxError("Variables and attributes may "
django.template.exceptions.TemplateSyntaxError: Variables and attributes may not begin with underscores: '_messages'
2021-11-11 22:30:54,584 django.request ERROR    Internal Server Error: /chats/
Traceback (most recent call last):
  File "C:\Users\tarlo\AppData\Local\Programs\Python\Python39\lib\site-packages\django\db\backends\utils.py", line 84, in _execute
    return self.cursor.execute(sql, params)
psycopg2.errors.UndefinedTable: ОШИБКА:  отношение "users" не существует
LINE 1: SELECT username from Users group by username
                             ^


The above exception was the direct cause of the following exception:

Traceback (most recent call last):
  File "C:\Users\tarlo\AppData\Local\Programs\Python\Python39\lib\site-packages\django\core\handlers\exception.py", line 47, in inner
    response = get_response(request)
  File "C:\Users\tarlo\AppData\Local\Programs\Python\Python39\lib\site-packages\django\core\handlers\base.py", line 181, in _get_response
    response = wrapped_callback(request, *callback_args, **callback_kwargs)
  File "C:\Users\tarlo\AppData\Local\Programs\Python\Python39\lib\site-packages\django\views\generic\base.py", line 70, in view
    return self.dispatch(request, *args, **kwargs)
  File "C:\Users\tarlo\AppData\Local\Programs\Python\Python39\lib\site-packages\django\views\generic\base.py", line 98, in dispatch
    return handler(request, *args, **kwargs)
  File "C:\Users\tarlo\Desktop\Code\Python\instamiligram\chat\views.py", line 13, in get
    return render(
  File "C:\Users\tarlo\AppData\Local\Programs\Python\Python39\lib\site-packages\django\shortcuts.py", line 19, in render
    content = loader.render_to_string(template_name, context, request, using=using)
  File "C:\Users\tarlo\AppData\Local\Programs\Python\Python39\lib\site-packages\django\template\loader.py", line 62, in render_to_string
    return template.render(context, request)
  File "C:\Users\tarlo\AppData\Local\Programs\Python\Python39\lib\site-packages\django\template\backends\django.py", line 61, in render
    return self.template.render(context)
  File "C:\Users\tarlo\AppData\Local\Programs\Python\Python39\lib\site-packages\django\template\base.py", line 170, in render
    return self._render(context)
  File "C:\Users\tarlo\AppData\Local\Programs\Python\Python39\lib\site-packages\django\template\base.py", line 162, in _render
    return self.nodelist.render(context)
  File "C:\Users\tarlo\AppData\Local\Programs\Python\Python39\lib\site-packages\django\template\base.py", line 938, in render
    bit = node.render_annotated(context)
  File "C:\Users\tarlo\AppData\Local\Programs\Python\Python39\lib\site-packages\django\template\base.py", line 905, in render_annotated
    return self.render(context)
  File "C:\Users\tarlo\AppData\Local\Programs\Python\Python39\lib\site-packages\django\template\loader_tags.py", line 150, in render
    return compiled_parent._render(context)
  File "C:\Users\tarlo\AppData\Local\Programs\Python\Python39\lib\site-packages\django\template\base.py", line 162, in _render
    return self.nodelist.render(context)
  File "C:\Users\tarlo\AppData\Local\Programs\Python\Python39\lib\site-packages\django\template\base.py", line 938, in render
    bit = node.render_annotated(context)
  File "C:\Users\tarlo\AppData\Local\Programs\Python\Python39\lib\site-packages\django\template\base.py", line 905, in render_annotated
    return self.render(context)
  File "C:\Users\tarlo\AppData\Local\Programs\Python\Python39\lib\site-packages\django\template\loader_tags.py", line 62, in render
    result = block.nodelist.render(context)
  File "C:\Users\tarlo\AppData\Local\Programs\Python\Python39\lib\site-packages\django\template\base.py", line 938, in render
    bit = node.render_annotated(context)
  File "C:\Users\tarlo\AppData\Local\Programs\Python\Python39\lib\site-packages\django\template\base.py", line 905, in render_annotated
    return self.render(context)
  File "C:\Users\tarlo\AppData\Local\Programs\Python\Python39\lib\site-packages\django\template\defaulttags.py", line 168, in render
    len_values = len(values)
  File "C:\Users\tarlo\AppData\Local\Programs\Python\Python39\lib\site-packages\django\db\models\query.py", line 1476, in __len__
    self._fetch_all()
  File "C:\Users\tarlo\AppData\Local\Programs\Python\Python39\lib\site-packages\django\db\models\query.py", line 1471, in _fetch_all
    self._result_cache = list(self.iterator())
  File "C:\Users\tarlo\AppData\Local\Programs\Python\Python39\lib\site-packages\django\db\models\query.py", line 1494, in iterator
    query = iter(self.query)
  File "C:\Users\tarlo\AppData\Local\Programs\Python\Python39\lib\site-packages\django\db\models\sql\query.py", line 101, in __iter__
    self._execute_query()
  File "C:\Users\tarlo\AppData\Local\Programs\Python\Python39\lib\site-packages\django\db\models\sql\query.py", line 141, in _execute_query
    self.cursor.execute(self.sql, params)
  File "C:\Users\tarlo\AppData\Local\Programs\Python\Python39\lib\site-packages\django\db\backends\utils.py", line 98, in execute
    return super().execute(sql, params)
  File "C:\Users\tarlo\AppData\Local\Programs\Python\Python39\lib\site-packages\django\db\backends\utils.py", line 66, in execute
    return self._execute_with_wrappers(sql, params, many=False, executor=self._execute)
  File "C:\Users\tarlo\AppData\Local\Programs\Python\Python39\lib\site-packages\django\db\backends\utils.py", line 75, in _execute_with_wrappers
    return executor(sql, params, many, context)
  File "C:\Users\tarlo\AppData\Local\Programs\Python\Python39\lib\site-packages\django\db\backends\utils.py", line 84, in _execute
    return self.cursor.execute(sql, params)
  File "C:\Users\tarlo\AppData\Local\Programs\Python\Python39\lib\site-packages\django\db\utils.py", line 90, in __exit__
    raise dj_exc_value.with_traceback(traceback) from exc_value
  File "C:\Users\tarlo\AppData\Local\Programs\Python\Python39\lib\site-packages\django\db\backends\utils.py", line 84, in _execute
    return self.cursor.execute(sql, params)
django.db.utils.ProgrammingError: ОШИБКА:  отношение "users" не существует
LINE 1: SELECT username from Users group by username
                             ^

2021-11-11 22:31:37,397 django.request ERROR    Internal Server Error: /chats/
Traceback (most recent call last):
  File "C:\Users\tarlo\AppData\Local\Programs\Python\Python39\lib\site-packages\django\core\handlers\exception.py", line 47, in inner
    response = get_response(request)
  File "C:\Users\tarlo\AppData\Local\Programs\Python\Python39\lib\site-packages\django\core\handlers\base.py", line 181, in _get_response
    response = wrapped_callback(request, *callback_args, **callback_kwargs)
  File "C:\Users\tarlo\AppData\Local\Programs\Python\Python39\lib\site-packages\django\views\generic\base.py", line 70, in view
    return self.dispatch(request, *args, **kwargs)
  File "C:\Users\tarlo\AppData\Local\Programs\Python\Python39\lib\site-packages\django\views\generic\base.py", line 98, in dispatch
    return handler(request, *args, **kwargs)
  File "C:\Users\tarlo\Desktop\Code\Python\instamiligram\chat\views.py", line 13, in get
    return render(
  File "C:\Users\tarlo\AppData\Local\Programs\Python\Python39\lib\site-packages\django\shortcuts.py", line 19, in render
    content = loader.render_to_string(template_name, context, request, using=using)
  File "C:\Users\tarlo\AppData\Local\Programs\Python\Python39\lib\site-packages\django\template\loader.py", line 62, in render_to_string
    return template.render(context, request)
  File "C:\Users\tarlo\AppData\Local\Programs\Python\Python39\lib\site-packages\django\template\backends\django.py", line 61, in render
    return self.template.render(context)
  File "C:\Users\tarlo\AppData\Local\Programs\Python\Python39\lib\site-packages\django\template\base.py", line 170, in render
    return self._render(context)
  File "C:\Users\tarlo\AppData\Local\Programs\Python\Python39\lib\site-packages\django\template\base.py", line 162, in _render
    return self.nodelist.render(context)
  File "C:\Users\tarlo\AppData\Local\Programs\Python\Python39\lib\site-packages\django\template\base.py", line 938, in render
    bit = node.render_annotated(context)
  File "C:\Users\tarlo\AppData\Local\Programs\Python\Python39\lib\site-packages\django\template\base.py", line 905, in render_annotated
    return self.render(context)
  File "C:\Users\tarlo\AppData\Local\Programs\Python\Python39\lib\site-packages\django\template\loader_tags.py", line 150, in render
    return compiled_parent._render(context)
  File "C:\Users\tarlo\AppData\Local\Programs\Python\Python39\lib\site-packages\django\template\base.py", line 162, in _render
    return self.nodelist.render(context)
  File "C:\Users\tarlo\AppData\Local\Programs\Python\Python39\lib\site-packages\django\template\base.py", line 938, in render
    bit = node.render_annotated(context)
  File "C:\Users\tarlo\AppData\Local\Programs\Python\Python39\lib\site-packages\django\template\base.py", line 905, in render_annotated
    return self.render(context)
  File "C:\Users\tarlo\AppData\Local\Programs\Python\Python39\lib\site-packages\django\template\loader_tags.py", line 62, in render
    result = block.nodelist.render(context)
  File "C:\Users\tarlo\AppData\Local\Programs\Python\Python39\lib\site-packages\django\template\base.py", line 938, in render
    bit = node.render_annotated(context)
  File "C:\Users\tarlo\AppData\Local\Programs\Python\Python39\lib\site-packages\django\template\base.py", line 905, in render_annotated
    return self.render(context)
  File "C:\Users\tarlo\AppData\Local\Programs\Python\Python39\lib\site-packages\django\template\defaulttags.py", line 168, in render
    len_values = len(values)
  File "C:\Users\tarlo\AppData\Local\Programs\Python\Python39\lib\site-packages\django\db\models\query.py", line 1476, in __len__
    self._fetch_all()
  File "C:\Users\tarlo\AppData\Local\Programs\Python\Python39\lib\site-packages\django\db\models\query.py", line 1471, in _fetch_all
    self._result_cache = list(self.iterator())
  File "C:\Users\tarlo\AppData\Local\Programs\Python\Python39\lib\site-packages\django\db\models\query.py", line 1499, in iterator
    raise exceptions.FieldDoesNotExist(
django.core.exceptions.FieldDoesNotExist: Raw query must include the primary key
2021-11-11 22:45:55,358 django.request ERROR    Internal Server Error: /chats/
Traceback (most recent call last):
  File "C:\Users\tarlo\AppData\Local\Programs\Python\Python39\lib\site-packages\django\core\handlers\exception.py", line 47, in inner
    response = get_response(request)
  File "C:\Users\tarlo\AppData\Local\Programs\Python\Python39\lib\site-packages\django\core\handlers\base.py", line 181, in _get_response
    response = wrapped_callback(request, *callback_args, **callback_kwargs)
  File "C:\Users\tarlo\AppData\Local\Programs\Python\Python39\lib\site-packages\django\views\generic\base.py", line 70, in view
    return self.dispatch(request, *args, **kwargs)
  File "C:\Users\tarlo\AppData\Local\Programs\Python\Python39\lib\site-packages\django\views\generic\base.py", line 98, in dispatch
    return handler(request, *args, **kwargs)
  File "C:\Users\tarlo\Desktop\Code\Python\instamiligram\chat\views.py", line 13, in get
    return render(
  File "C:\Users\tarlo\AppData\Local\Programs\Python\Python39\lib\site-packages\django\shortcuts.py", line 19, in render
    content = loader.render_to_string(template_name, context, request, using=using)
  File "C:\Users\tarlo\AppData\Local\Programs\Python\Python39\lib\site-packages\django\template\loader.py", line 62, in render_to_string
    return template.render(context, request)
  File "C:\Users\tarlo\AppData\Local\Programs\Python\Python39\lib\site-packages\django\template\backends\django.py", line 61, in render
    return self.template.render(context)
  File "C:\Users\tarlo\AppData\Local\Programs\Python\Python39\lib\site-packages\django\template\base.py", line 170, in render
    return self._render(context)
  File "C:\Users\tarlo\AppData\Local\Programs\Python\Python39\lib\site-packages\django\template\base.py", line 162, in _render
    return self.nodelist.render(context)
  File "C:\Users\tarlo\AppData\Local\Programs\Python\Python39\lib\site-packages\django\template\base.py", line 938, in render
    bit = node.render_annotated(context)
  File "C:\Users\tarlo\AppData\Local\Programs\Python\Python39\lib\site-packages\django\template\base.py", line 905, in render_annotated
    return self.render(context)
  File "C:\Users\tarlo\AppData\Local\Programs\Python\Python39\lib\site-packages\django\template\loader_tags.py", line 150, in render
    return compiled_parent._render(context)
  File "C:\Users\tarlo\AppData\Local\Programs\Python\Python39\lib\site-packages\django\template\base.py", line 162, in _render
    return self.nodelist.render(context)
  File "C:\Users\tarlo\AppData\Local\Programs\Python\Python39\lib\site-packages\django\template\base.py", line 938, in render
    bit = node.render_annotated(context)
  File "C:\Users\tarlo\AppData\Local\Programs\Python\Python39\lib\site-packages\django\template\base.py", line 905, in render_annotated
    return self.render(context)
  File "C:\Users\tarlo\AppData\Local\Programs\Python\Python39\lib\site-packages\django\template\loader_tags.py", line 62, in render
    result = block.nodelist.render(context)
  File "C:\Users\tarlo\AppData\Local\Programs\Python\Python39\lib\site-packages\django\template\base.py", line 938, in render
    bit = node.render_annotated(context)
  File "C:\Users\tarlo\AppData\Local\Programs\Python\Python39\lib\site-packages\django\template\base.py", line 905, in render_annotated
    return self.render(context)
  File "C:\Users\tarlo\AppData\Local\Programs\Python\Python39\lib\site-packages\django\template\defaulttags.py", line 167, in render
    values = list(values)
TypeError: 'RelatedManager' object is not iterable
2021-11-12 16:38:36,929 django.request WARNING  Not Found: /favicon.ico
2021-11-12 17:00:26,980 django.request ERROR    Internal Server Error: /chats/
Traceback (most recent call last):
  File "C:\Users\tarlo\Desktop\Code\DJANGO\instamiligram\venv\lib\site-packages\django\template\defaulttags.py", line 1034, in find_library
    return parser.libraries[name]
KeyError: 'chat_tags'

During handling of the above exception, another exception occurred:

Traceback (most recent call last):
  File "C:\Users\tarlo\Desktop\Code\DJANGO\instamiligram\venv\lib\site-packages\django\core\handlers\exception.py", line 47, in inner
    response = get_response(request)
  File "C:\Users\tarlo\Desktop\Code\DJANGO\instamiligram\venv\lib\site-packages\django\core\handlers\base.py", line 181, in _get_response
    response = wrapped_callback(request, *callback_args, **callback_kwargs)
  File "C:\Users\tarlo\Desktop\Code\DJANGO\instamiligram\venv\lib\site-packages\django\views\generic\base.py", line 70, in view
    return self.dispatch(request, *args, **kwargs)
  File "C:\Users\tarlo\Desktop\Code\DJANGO\instamiligram\venv\lib\site-packages\django\views\generic\base.py", line 98, in dispatch
    return handler(request, *args, **kwargs)
  File "C:\Users\tarlo\Desktop\Code\DJANGO\instamiligram\chat\views.py", line 18, in get
    return render(
  File "C:\Users\tarlo\Desktop\Code\DJANGO\instamiligram\venv\lib\site-packages\django\shortcuts.py", line 19, in render
    content = loader.render_to_string(template_name, context, request, using=using)
  File "C:\Users\tarlo\Desktop\Code\DJANGO\instamiligram\venv\lib\site-packages\django\template\loader.py", line 61, in render_to_string
    template = get_template(template_name, using=using)
  File "C:\Users\tarlo\Desktop\Code\DJANGO\instamiligram\venv\lib\site-packages\django\template\loader.py", line 15, in get_template
    return engine.get_template(template_name)
  File "C:\Users\tarlo\Desktop\Code\DJANGO\instamiligram\venv\lib\site-packages\django\template\backends\django.py", line 34, in get_template
    return Template(self.engine.get_template(template_name), self)
  File "C:\Users\tarlo\Desktop\Code\DJANGO\instamiligram\venv\lib\site-packages\django\template\engine.py", line 143, in get_template
    template, origin = self.find_template(template_name)
  File "C:\Users\tarlo\Desktop\Code\DJANGO\instamiligram\venv\lib\site-packages\django\template\engine.py", line 125, in find_template
    template = loader.get_template(name, skip=skip)
  File "C:\Users\tarlo\Desktop\Code\DJANGO\instamiligram\venv\lib\site-packages\django\template\loaders\base.py", line 29, in get_template
    return Template(
  File "C:\Users\tarlo\Desktop\Code\DJANGO\instamiligram\venv\lib\site-packages\django\template\base.py", line 155, in __init__
    self.nodelist = self.compile_nodelist()
  File "C:\Users\tarlo\Desktop\Code\DJANGO\instamiligram\venv\lib\site-packages\django\template\base.py", line 193, in compile_nodelist
    return parser.parse()
  File "C:\Users\tarlo\Desktop\Code\DJANGO\instamiligram\venv\lib\site-packages\django\template\base.py", line 478, in parse
    raise self.error(token, e)
  File "C:\Users\tarlo\Desktop\Code\DJANGO\instamiligram\venv\lib\site-packages\django\template\base.py", line 476, in parse
    compiled_result = compile_func(self, token)
  File "C:\Users\tarlo\Desktop\Code\DJANGO\instamiligram\venv\lib\site-packages\django\template\loader_tags.py", line 278, in do_extends
    nodelist = parser.parse()
  File "C:\Users\tarlo\Desktop\Code\DJANGO\instamiligram\venv\lib\site-packages\django\template\base.py", line 478, in parse
    raise self.error(token, e)
  File "C:\Users\tarlo\Desktop\Code\DJANGO\instamiligram\venv\lib\site-packages\django\template\base.py", line 476, in parse
    compiled_result = compile_func(self, token)
  File "C:\Users\tarlo\Desktop\Code\DJANGO\instamiligram\venv\lib\site-packages\django\template\loader_tags.py", line 216, in do_block
    nodelist = parser.parse(('endblock',))
  File "C:\Users\tarlo\Desktop\Code\DJANGO\instamiligram\venv\lib\site-packages\django\template\base.py", line 478, in parse
    raise self.error(token, e)
  File "C:\Users\tarlo\Desktop\Code\DJANGO\instamiligram\venv\lib\site-packages\django\template\base.py", line 476, in parse
    compiled_result = compile_func(self, token)
  File "C:\Users\tarlo\Desktop\Code\DJANGO\instamiligram\venv\lib\site-packages\django\template\defaulttags.py", line 1091, in load
    lib = find_library(parser, name)
  File "C:\Users\tarlo\Desktop\Code\DJANGO\instamiligram\venv\lib\site-packages\django\template\defaulttags.py", line 1036, in find_library
    raise TemplateSyntaxError(
django.template.exceptions.TemplateSyntaxError: 'chat_tags' is not a registered tag library. Must be one of:
admin_list
admin_modify
admin_urls
cache
crispy_forms_field
crispy_forms_filters
crispy_forms_tags
crispy_forms_utils
i18n
instagram_tags
l10n
log
static
tags
tz
user_tags
2021-11-12 17:01:06,956 django.request ERROR    Internal Server Error: /chats/
Traceback (most recent call last):
  File "C:\Users\tarlo\Desktop\Code\DJANGO\instamiligram\venv\lib\site-packages\django\template\base.py", line 454, in parse
    command = token.contents.split()[0]
IndexError: list index out of range

During handling of the above exception, another exception occurred:

Traceback (most recent call last):
  File "C:\Users\tarlo\Desktop\Code\DJANGO\instamiligram\venv\lib\site-packages\django\core\handlers\exception.py", line 47, in inner
    response = get_response(request)
  File "C:\Users\tarlo\Desktop\Code\DJANGO\instamiligram\venv\lib\site-packages\django\core\handlers\base.py", line 181, in _get_response
    response = wrapped_callback(request, *callback_args, **callback_kwargs)
  File "C:\Users\tarlo\Desktop\Code\DJANGO\instamiligram\venv\lib\site-packages\django\views\generic\base.py", line 70, in view
    return self.dispatch(request, *args, **kwargs)
  File "C:\Users\tarlo\Desktop\Code\DJANGO\instamiligram\venv\lib\site-packages\django\views\generic\base.py", line 98, in dispatch
    return handler(request, *args, **kwargs)
  File "C:\Users\tarlo\Desktop\Code\DJANGO\instamiligram\chat\views.py", line 18, in get
    return render(
  File "C:\Users\tarlo\Desktop\Code\DJANGO\instamiligram\venv\lib\site-packages\django\shortcuts.py", line 19, in render
    content = loader.render_to_string(template_name, context, request, using=using)
  File "C:\Users\tarlo\Desktop\Code\DJANGO\instamiligram\venv\lib\site-packages\django\template\loader.py", line 61, in render_to_string
    template = get_template(template_name, using=using)
  File "C:\Users\tarlo\Desktop\Code\DJANGO\instamiligram\venv\lib\site-packages\django\template\loader.py", line 15, in get_template
    return engine.get_template(template_name)
  File "C:\Users\tarlo\Desktop\Code\DJANGO\instamiligram\venv\lib\site-packages\django\template\backends\django.py", line 34, in get_template
    return Template(self.engine.get_template(template_name), self)
  File "C:\Users\tarlo\Desktop\Code\DJANGO\instamiligram\venv\lib\site-packages\django\template\engine.py", line 143, in get_template
    template, origin = self.find_template(template_name)
  File "C:\Users\tarlo\Desktop\Code\DJANGO\instamiligram\venv\lib\site-packages\django\template\engine.py", line 125, in find_template
    template = loader.get_template(name, skip=skip)
  File "C:\Users\tarlo\Desktop\Code\DJANGO\instamiligram\venv\lib\site-packages\django\template\loaders\base.py", line 29, in get_template
    return Template(
  File "C:\Users\tarlo\Desktop\Code\DJANGO\instamiligram\venv\lib\site-packages\django\template\base.py", line 155, in __init__
    self.nodelist = self.compile_nodelist()
  File "C:\Users\tarlo\Desktop\Code\DJANGO\instamiligram\venv\lib\site-packages\django\template\base.py", line 193, in compile_nodelist
    return parser.parse()
  File "C:\Users\tarlo\Desktop\Code\DJANGO\instamiligram\venv\lib\site-packages\django\template\base.py", line 478, in parse
    raise self.error(token, e)
  File "C:\Users\tarlo\Desktop\Code\DJANGO\instamiligram\venv\lib\site-packages\django\template\base.py", line 476, in parse
    compiled_result = compile_func(self, token)
  File "C:\Users\tarlo\Desktop\Code\DJANGO\instamiligram\venv\lib\site-packages\django\template\loader_tags.py", line 278, in do_extends
    nodelist = parser.parse()
  File "C:\Users\tarlo\Desktop\Code\DJANGO\instamiligram\venv\lib\site-packages\django\template\base.py", line 478, in parse
    raise self.error(token, e)
  File "C:\Users\tarlo\Desktop\Code\DJANGO\instamiligram\venv\lib\site-packages\django\template\base.py", line 476, in parse
    compiled_result = compile_func(self, token)
  File "C:\Users\tarlo\Desktop\Code\DJANGO\instamiligram\venv\lib\site-packages\django\template\loader_tags.py", line 216, in do_block
    nodelist = parser.parse(('endblock',))
  File "C:\Users\tarlo\Desktop\Code\DJANGO\instamiligram\venv\lib\site-packages\django\template\base.py", line 478, in parse
    raise self.error(token, e)
  File "C:\Users\tarlo\Desktop\Code\DJANGO\instamiligram\venv\lib\site-packages\django\template\base.py", line 476, in parse
    compiled_result = compile_func(self, token)
  File "C:\Users\tarlo\Desktop\Code\DJANGO\instamiligram\venv\lib\site-packages\django\template\defaulttags.py", line 814, in do_for
    nodelist_loop = parser.parse(('empty', 'endfor',))
  File "C:\Users\tarlo\Desktop\Code\DJANGO\instamiligram\venv\lib\site-packages\django\template\base.py", line 456, in parse
    raise self.error(token, 'Empty block tag on line %d' % token.lineno)
django.template.exceptions.TemplateSyntaxError: Empty block tag on line 31
2021-11-12 17:19:49,772 django.request ERROR    Internal Server Error: /chats/
Traceback (most recent call last):
  File "C:\Users\tarlo\Desktop\Code\DJANGO\instamiligram\venv\lib\site-packages\django\core\handlers\exception.py", line 47, in inner
    response = get_response(request)
  File "C:\Users\tarlo\Desktop\Code\DJANGO\instamiligram\venv\lib\site-packages\django\core\handlers\base.py", line 181, in _get_response
    response = wrapped_callback(request, *callback_args, **callback_kwargs)
  File "C:\Users\tarlo\Desktop\Code\DJANGO\instamiligram\venv\lib\site-packages\django\views\generic\base.py", line 70, in view
    return self.dispatch(request, *args, **kwargs)
  File "C:\Users\tarlo\Desktop\Code\DJANGO\instamiligram\venv\lib\site-packages\django\views\generic\base.py", line 98, in dispatch
    return handler(request, *args, **kwargs)
  File "C:\Users\tarlo\Desktop\Code\DJANGO\instamiligram\chat\views.py", line 19, in get
    return render(
  File "C:\Users\tarlo\Desktop\Code\DJANGO\instamiligram\venv\lib\site-packages\django\shortcuts.py", line 19, in render
    content = loader.render_to_string(template_name, context, request, using=using)
  File "C:\Users\tarlo\Desktop\Code\DJANGO\instamiligram\venv\lib\site-packages\django\template\loader.py", line 62, in render_to_string
    return template.render(context, request)
  File "C:\Users\tarlo\Desktop\Code\DJANGO\instamiligram\venv\lib\site-packages\django\template\backends\django.py", line 61, in render
    return self.template.render(context)
  File "C:\Users\tarlo\Desktop\Code\DJANGO\instamiligram\venv\lib\site-packages\django\template\base.py", line 170, in render
    return self._render(context)
  File "C:\Users\tarlo\Desktop\Code\DJANGO\instamiligram\venv\lib\site-packages\django\template\base.py", line 162, in _render
    return self.nodelist.render(context)
  File "C:\Users\tarlo\Desktop\Code\DJANGO\instamiligram\venv\lib\site-packages\django\template\base.py", line 938, in render
    bit = node.render_annotated(context)
  File "C:\Users\tarlo\Desktop\Code\DJANGO\instamiligram\venv\lib\site-packages\django\template\base.py", line 905, in render_annotated
    return self.render(context)
  File "C:\Users\tarlo\Desktop\Code\DJANGO\instamiligram\venv\lib\site-packages\django\template\loader_tags.py", line 150, in render
    return compiled_parent._render(context)
  File "C:\Users\tarlo\Desktop\Code\DJANGO\instamiligram\venv\lib\site-packages\django\template\base.py", line 162, in _render
    return self.nodelist.render(context)
  File "C:\Users\tarlo\Desktop\Code\DJANGO\instamiligram\venv\lib\site-packages\django\template\base.py", line 938, in render
    bit = node.render_annotated(context)
  File "C:\Users\tarlo\Desktop\Code\DJANGO\instamiligram\venv\lib\site-packages\django\template\base.py", line 905, in render_annotated
    return self.render(context)
  File "C:\Users\tarlo\Desktop\Code\DJANGO\instamiligram\venv\lib\site-packages\django\template\loader_tags.py", line 62, in render
    result = block.nodelist.render(context)
  File "C:\Users\tarlo\Desktop\Code\DJANGO\instamiligram\venv\lib\site-packages\django\template\base.py", line 938, in render
    bit = node.render_annotated(context)
  File "C:\Users\tarlo\Desktop\Code\DJANGO\instamiligram\venv\lib\site-packages\django\template\base.py", line 905, in render_annotated
    return self.render(context)
  File "C:\Users\tarlo\Desktop\Code\DJANGO\instamiligram\venv\lib\site-packages\django\template\defaulttags.py", line 211, in render
    nodelist.append(node.render_annotated(context))
  File "C:\Users\tarlo\Desktop\Code\DJANGO\instamiligram\venv\lib\site-packages\django\template\base.py", line 905, in render_annotated
    return self.render(context)
  File "C:\Users\tarlo\Desktop\Code\DJANGO\instamiligram\venv\lib\site-packages\django\template\defaulttags.py", line 446, in render
    url = reverse(view_name, args=args, kwargs=kwargs, current_app=current_app)
  File "C:\Users\tarlo\Desktop\Code\DJANGO\instamiligram\venv\lib\site-packages\django\urls\base.py", line 86, in reverse
    return resolver._reverse_with_prefix(view, prefix, *args, **kwargs)
  File "C:\Users\tarlo\Desktop\Code\DJANGO\instamiligram\venv\lib\site-packages\django\urls\resolvers.py", line 694, in _reverse_with_prefix
    raise NoReverseMatch(msg)
django.urls.exceptions.NoReverseMatch: Reverse for 'chat-dialog' not found. 'chat-dialog' is not a valid view function or pattern name.
2021-11-12 17:19:58,852 django.request ERROR    Internal Server Error: /chats/
Traceback (most recent call last):
  File "C:\Users\tarlo\Desktop\Code\DJANGO\instamiligram\venv\lib\site-packages\django\core\handlers\exception.py", line 47, in inner
    response = get_response(request)
  File "C:\Users\tarlo\Desktop\Code\DJANGO\instamiligram\venv\lib\site-packages\django\core\handlers\base.py", line 181, in _get_response
    response = wrapped_callback(request, *callback_args, **callback_kwargs)
  File "C:\Users\tarlo\Desktop\Code\DJANGO\instamiligram\venv\lib\site-packages\django\views\generic\base.py", line 70, in view
    return self.dispatch(request, *args, **kwargs)
  File "C:\Users\tarlo\Desktop\Code\DJANGO\instamiligram\venv\lib\site-packages\django\views\generic\base.py", line 98, in dispatch
    return handler(request, *args, **kwargs)
  File "C:\Users\tarlo\Desktop\Code\DJANGO\instamiligram\chat\views.py", line 19, in get
    return render(
  File "C:\Users\tarlo\Desktop\Code\DJANGO\instamiligram\venv\lib\site-packages\django\shortcuts.py", line 19, in render
    content = loader.render_to_string(template_name, context, request, using=using)
  File "C:\Users\tarlo\Desktop\Code\DJANGO\instamiligram\venv\lib\site-packages\django\template\loader.py", line 62, in render_to_string
    return template.render(context, request)
  File "C:\Users\tarlo\Desktop\Code\DJANGO\instamiligram\venv\lib\site-packages\django\template\backends\django.py", line 61, in render
    return self.template.render(context)
  File "C:\Users\tarlo\Desktop\Code\DJANGO\instamiligram\venv\lib\site-packages\django\template\base.py", line 170, in render
    return self._render(context)
  File "C:\Users\tarlo\Desktop\Code\DJANGO\instamiligram\venv\lib\site-packages\django\template\base.py", line 162, in _render
    return self.nodelist.render(context)
  File "C:\Users\tarlo\Desktop\Code\DJANGO\instamiligram\venv\lib\site-packages\django\template\base.py", line 938, in render
    bit = node.render_annotated(context)
  File "C:\Users\tarlo\Desktop\Code\DJANGO\instamiligram\venv\lib\site-packages\django\template\base.py", line 905, in render_annotated
    return self.render(context)
  File "C:\Users\tarlo\Desktop\Code\DJANGO\instamiligram\venv\lib\site-packages\django\template\loader_tags.py", line 150, in render
    return compiled_parent._render(context)
  File "C:\Users\tarlo\Desktop\Code\DJANGO\instamiligram\venv\lib\site-packages\django\template\base.py", line 162, in _render
    return self.nodelist.render(context)
  File "C:\Users\tarlo\Desktop\Code\DJANGO\instamiligram\venv\lib\site-packages\django\template\base.py", line 938, in render
    bit = node.render_annotated(context)
  File "C:\Users\tarlo\Desktop\Code\DJANGO\instamiligram\venv\lib\site-packages\django\template\base.py", line 905, in render_annotated
    return self.render(context)
  File "C:\Users\tarlo\Desktop\Code\DJANGO\instamiligram\venv\lib\site-packages\django\template\loader_tags.py", line 62, in render
    result = block.nodelist.render(context)
  File "C:\Users\tarlo\Desktop\Code\DJANGO\instamiligram\venv\lib\site-packages\django\template\base.py", line 938, in render
    bit = node.render_annotated(context)
  File "C:\Users\tarlo\Desktop\Code\DJANGO\instamiligram\venv\lib\site-packages\django\template\base.py", line 905, in render_annotated
    return self.render(context)
  File "C:\Users\tarlo\Desktop\Code\DJANGO\instamiligram\venv\lib\site-packages\django\template\defaulttags.py", line 211, in render
    nodelist.append(node.render_annotated(context))
  File "C:\Users\tarlo\Desktop\Code\DJANGO\instamiligram\venv\lib\site-packages\django\template\base.py", line 905, in render_annotated
    return self.render(context)
  File "C:\Users\tarlo\Desktop\Code\DJANGO\instamiligram\venv\lib\site-packages\django\template\defaulttags.py", line 446, in render
    url = reverse(view_name, args=args, kwargs=kwargs, current_app=current_app)
  File "C:\Users\tarlo\Desktop\Code\DJANGO\instamiligram\venv\lib\site-packages\django\urls\base.py", line 86, in reverse
    return resolver._reverse_with_prefix(view, prefix, *args, **kwargs)
  File "C:\Users\tarlo\Desktop\Code\DJANGO\instamiligram\venv\lib\site-packages\django\urls\resolvers.py", line 694, in _reverse_with_prefix
    raise NoReverseMatch(msg)
django.urls.exceptions.NoReverseMatch: Reverse for 'chats-dialog' not found. 'chats-dialog' is not a valid view function or pattern name.
2021-11-12 18:14:23,577 django.request ERROR    Internal Server Error: /chat/koji
Traceback (most recent call last):
  File "C:\Users\tarlo\Desktop\Code\DJANGO\instamiligram\venv\lib\site-packages\django\core\handlers\exception.py", line 47, in inner
    response = get_response(request)
  File "C:\Users\tarlo\Desktop\Code\DJANGO\instamiligram\venv\lib\site-packages\django\core\handlers\base.py", line 181, in _get_response
    response = wrapped_callback(request, *callback_args, **callback_kwargs)
  File "C:\Users\tarlo\Desktop\Code\DJANGO\instamiligram\venv\lib\site-packages\django\views\generic\base.py", line 70, in view
    return self.dispatch(request, *args, **kwargs)
  File "C:\Users\tarlo\Desktop\Code\DJANGO\instamiligram\venv\lib\site-packages\django\views\generic\base.py", line 98, in dispatch
    return handler(request, *args, **kwargs)
  File "C:\Users\tarlo\Desktop\Code\DJANGO\instamiligram\chat\views.py", line 31, in get
    _messages = Message.objects.filter(sender=u_target).filter(
TypeError: unsupported operand type(s) for +: 'QuerySet' and 'QuerySet'
2021-11-12 18:14:37,699 django.request ERROR    Internal Server Error: /chat/koji
Traceback (most recent call last):
  File "C:\Users\tarlo\Desktop\Code\DJANGO\instamiligram\venv\lib\site-packages\django\core\handlers\exception.py", line 47, in inner
    response = get_response(request)
  File "C:\Users\tarlo\Desktop\Code\DJANGO\instamiligram\venv\lib\site-packages\django\core\handlers\base.py", line 181, in _get_response
    response = wrapped_callback(request, *callback_args, **callback_kwargs)
  File "C:\Users\tarlo\Desktop\Code\DJANGO\instamiligram\venv\lib\site-packages\django\views\generic\base.py", line 70, in view
    return self.dispatch(request, *args, **kwargs)
  File "C:\Users\tarlo\Desktop\Code\DJANGO\instamiligram\venv\lib\site-packages\django\views\generic\base.py", line 98, in dispatch
    return handler(request, *args, **kwargs)
  File "C:\Users\tarlo\Desktop\Code\DJANGO\instamiligram\chat\views.py", line 31, in get
    _messages = Message.objects.filter(sender=u_target).filter(
TypeError: unsupported operand type(s) for +: 'QuerySet' and 'QuerySet'
2021-11-12 18:15:09,223 django.request ERROR    Internal Server Error: /chat/koji
Traceback (most recent call last):
  File "C:\Users\tarlo\Desktop\Code\DJANGO\instamiligram\venv\lib\site-packages\django\core\handlers\exception.py", line 47, in inner
    response = get_response(request)
  File "C:\Users\tarlo\Desktop\Code\DJANGO\instamiligram\venv\lib\site-packages\django\core\handlers\base.py", line 181, in _get_response
    response = wrapped_callback(request, *callback_args, **callback_kwargs)
  File "C:\Users\tarlo\Desktop\Code\DJANGO\instamiligram\venv\lib\site-packages\django\views\generic\base.py", line 70, in view
    return self.dispatch(request, *args, **kwargs)
  File "C:\Users\tarlo\Desktop\Code\DJANGO\instamiligram\venv\lib\site-packages\django\views\generic\base.py", line 98, in dispatch
    return handler(request, *args, **kwargs)
  File "C:\Users\tarlo\Desktop\Code\DJANGO\instamiligram\chat\views.py", line 31, in get
    _messages = Message.objects.filter(sender=u_target).filter(
TypeError: update() takes 1 positional argument but 2 were given
2021-11-12 18:16:10,552 django.request ERROR    Internal Server Error: /chat/koji
Traceback (most recent call last):
  File "C:\Users\tarlo\Desktop\Code\DJANGO\instamiligram\venv\lib\site-packages\django\core\handlers\exception.py", line 47, in inner
    response = get_response(request)
  File "C:\Users\tarlo\Desktop\Code\DJANGO\instamiligram\venv\lib\site-packages\django\core\handlers\base.py", line 181, in _get_response
    response = wrapped_callback(request, *callback_args, **callback_kwargs)
  File "C:\Users\tarlo\Desktop\Code\DJANGO\instamiligram\venv\lib\site-packages\django\views\generic\base.py", line 70, in view
    return self.dispatch(request, *args, **kwargs)
  File "C:\Users\tarlo\Desktop\Code\DJANGO\instamiligram\venv\lib\site-packages\django\views\generic\base.py", line 98, in dispatch
    return handler(request, *args, **kwargs)
  File "C:\Users\tarlo\Desktop\Code\DJANGO\instamiligram\chat\views.py", line 31, in get
    _messages = Message.objects.filter(sender=u_target).filter(
TypeError: raw() missing 1 required positional argument: 'raw_query'
2021-11-12 18:22:47,096 django.request WARNING  Not Found: /chas
2021-11-12 18:24:42,258 django.request ERROR    Internal Server Error: /chat/koji
Traceback (most recent call last):
  File "C:\Users\tarlo\Desktop\Code\DJANGO\instamiligram\venv\lib\site-packages\django\core\handlers\exception.py", line 47, in inner
    response = get_response(request)
  File "C:\Users\tarlo\Desktop\Code\DJANGO\instamiligram\venv\lib\site-packages\django\core\handlers\base.py", line 181, in _get_response
    response = wrapped_callback(request, *callback_args, **callback_kwargs)
  File "C:\Users\tarlo\Desktop\Code\DJANGO\instamiligram\venv\lib\site-packages\django\views\generic\base.py", line 70, in view
    return self.dispatch(request, *args, **kwargs)
  File "C:\Users\tarlo\Desktop\Code\DJANGO\instamiligram\venv\lib\site-packages\django\views\generic\base.py", line 98, in dispatch
    return handler(request, *args, **kwargs)
  File "C:\Users\tarlo\Desktop\Code\DJANGO\instamiligram\chat\views.py", line 40, in get
    'msgs': _messages + _messages2
TypeError: unsupported operand type(s) for +: 'QuerySet' and 'QuerySet'
2021-11-12 22:11:50,627 django.request WARNING  Not Found: /favicon.ico
2021-11-12 22:25:57,060 django.request ERROR    Internal Server Error: /profile/a
Traceback (most recent call last):
  File "C:\Users\tarlo\AppData\Local\Programs\Python\Python39\lib\site-packages\django\template\base.py", line 470, in parse
    compile_func = self.tags[command]
KeyError: 'get_user_posts'

During handling of the above exception, another exception occurred:

Traceback (most recent call last):
  File "C:\Users\tarlo\AppData\Local\Programs\Python\Python39\lib\site-packages\django\core\handlers\exception.py", line 47, in inner
    response = get_response(request)
  File "C:\Users\tarlo\AppData\Local\Programs\Python\Python39\lib\site-packages\django\core\handlers\base.py", line 181, in _get_response
    response = wrapped_callback(request, *callback_args, **callback_kwargs)
  File "C:\Users\tarlo\AppData\Local\Programs\Python\Python39\lib\site-packages\django\views\generic\base.py", line 70, in view
    return self.dispatch(request, *args, **kwargs)
  File "C:\Users\tarlo\AppData\Local\Programs\Python\Python39\lib\site-packages\django\views\generic\base.py", line 98, in dispatch
    return handler(request, *args, **kwargs)
  File "C:\Users\tarlo\Desktop\Code\Python\instamiligram\users\views.py", line 108, in get
    return render(request, "users/profile.html", {"user": User.objects.filter(username=username).first()})
  File "C:\Users\tarlo\AppData\Local\Programs\Python\Python39\lib\site-packages\django\shortcuts.py", line 19, in render
    content = loader.render_to_string(template_name, context, request, using=using)
  File "C:\Users\tarlo\AppData\Local\Programs\Python\Python39\lib\site-packages\django\template\loader.py", line 61, in render_to_string
    template = get_template(template_name, using=using)
  File "C:\Users\tarlo\AppData\Local\Programs\Python\Python39\lib\site-packages\django\template\loader.py", line 15, in get_template
    return engine.get_template(template_name)
  File "C:\Users\tarlo\AppData\Local\Programs\Python\Python39\lib\site-packages\django\template\backends\django.py", line 34, in get_template
    return Template(self.engine.get_template(template_name), self)
  File "C:\Users\tarlo\AppData\Local\Programs\Python\Python39\lib\site-packages\django\template\engine.py", line 143, in get_template
    template, origin = self.find_template(template_name)
  File "C:\Users\tarlo\AppData\Local\Programs\Python\Python39\lib\site-packages\django\template\engine.py", line 125, in find_template
    template = loader.get_template(name, skip=skip)
  File "C:\Users\tarlo\AppData\Local\Programs\Python\Python39\lib\site-packages\django\template\loaders\base.py", line 29, in get_template
    return Template(
  File "C:\Users\tarlo\AppData\Local\Programs\Python\Python39\lib\site-packages\django\template\base.py", line 155, in __init__
    self.nodelist = self.compile_nodelist()
  File "C:\Users\tarlo\AppData\Local\Programs\Python\Python39\lib\site-packages\django\template\base.py", line 193, in compile_nodelist
    return parser.parse()
  File "C:\Users\tarlo\AppData\Local\Programs\Python\Python39\lib\site-packages\django\template\base.py", line 478, in parse
    raise self.error(token, e)
  File "C:\Users\tarlo\AppData\Local\Programs\Python\Python39\lib\site-packages\django\template\base.py", line 476, in parse
    compiled_result = compile_func(self, token)
  File "C:\Users\tarlo\AppData\Local\Programs\Python\Python39\lib\site-packages\django\template\loader_tags.py", line 278, in do_extends
    nodelist = parser.parse()
  File "C:\Users\tarlo\AppData\Local\Programs\Python\Python39\lib\site-packages\django\template\base.py", line 472, in parse
    self.invalid_block_tag(token, command, parse_until)
  File "C:\Users\tarlo\AppData\Local\Programs\Python\Python39\lib\site-packages\django\template\base.py", line 531, in invalid_block_tag
    raise self.error(
django.template.exceptions.TemplateSyntaxError: Invalid block tag on line 3: 'get_user_posts'. Did you forget to register or load this tag?
2021-11-12 22:26:19,696 django.request ERROR    Internal Server Error: /profile/a
Traceback (most recent call last):
  File "C:\Users\tarlo\AppData\Local\Programs\Python\Python39\lib\site-packages\django\template\base.py", line 470, in parse
    compile_func = self.tags[command]
KeyError: 'get_user_posts'

During handling of the above exception, another exception occurred:

Traceback (most recent call last):
  File "C:\Users\tarlo\AppData\Local\Programs\Python\Python39\lib\site-packages\django\core\handlers\exception.py", line 47, in inner
    response = get_response(request)
  File "C:\Users\tarlo\AppData\Local\Programs\Python\Python39\lib\site-packages\django\core\handlers\base.py", line 181, in _get_response
    response = wrapped_callback(request, *callback_args, **callback_kwargs)
  File "C:\Users\tarlo\AppData\Local\Programs\Python\Python39\lib\site-packages\django\views\generic\base.py", line 70, in view
    return self.dispatch(request, *args, **kwargs)
  File "C:\Users\tarlo\AppData\Local\Programs\Python\Python39\lib\site-packages\django\views\generic\base.py", line 98, in dispatch
    return handler(request, *args, **kwargs)
  File "C:\Users\tarlo\Desktop\Code\Python\instamiligram\users\views.py", line 108, in get
    return render(request, "users/profile.html", {"user": User.objects.filter(username=username).first()})
  File "C:\Users\tarlo\AppData\Local\Programs\Python\Python39\lib\site-packages\django\shortcuts.py", line 19, in render
    content = loader.render_to_string(template_name, context, request, using=using)
  File "C:\Users\tarlo\AppData\Local\Programs\Python\Python39\lib\site-packages\django\template\loader.py", line 61, in render_to_string
    template = get_template(template_name, using=using)
  File "C:\Users\tarlo\AppData\Local\Programs\Python\Python39\lib\site-packages\django\template\loader.py", line 15, in get_template
    return engine.get_template(template_name)
  File "C:\Users\tarlo\AppData\Local\Programs\Python\Python39\lib\site-packages\django\template\backends\django.py", line 34, in get_template
    return Template(self.engine.get_template(template_name), self)
  File "C:\Users\tarlo\AppData\Local\Programs\Python\Python39\lib\site-packages\django\template\engine.py", line 143, in get_template
    template, origin = self.find_template(template_name)
  File "C:\Users\tarlo\AppData\Local\Programs\Python\Python39\lib\site-packages\django\template\engine.py", line 125, in find_template
    template = loader.get_template(name, skip=skip)
  File "C:\Users\tarlo\AppData\Local\Programs\Python\Python39\lib\site-packages\django\template\loaders\base.py", line 29, in get_template
    return Template(
  File "C:\Users\tarlo\AppData\Local\Programs\Python\Python39\lib\site-packages\django\template\base.py", line 155, in __init__
    self.nodelist = self.compile_nodelist()
  File "C:\Users\tarlo\AppData\Local\Programs\Python\Python39\lib\site-packages\django\template\base.py", line 193, in compile_nodelist
    return parser.parse()
  File "C:\Users\tarlo\AppData\Local\Programs\Python\Python39\lib\site-packages\django\template\base.py", line 478, in parse
    raise self.error(token, e)
  File "C:\Users\tarlo\AppData\Local\Programs\Python\Python39\lib\site-packages\django\template\base.py", line 476, in parse
    compiled_result = compile_func(self, token)
  File "C:\Users\tarlo\AppData\Local\Programs\Python\Python39\lib\site-packages\django\template\loader_tags.py", line 278, in do_extends
    nodelist = parser.parse()
  File "C:\Users\tarlo\AppData\Local\Programs\Python\Python39\lib\site-packages\django\template\base.py", line 472, in parse
    self.invalid_block_tag(token, command, parse_until)
  File "C:\Users\tarlo\AppData\Local\Programs\Python\Python39\lib\site-packages\django\template\base.py", line 531, in invalid_block_tag
    raise self.error(
django.template.exceptions.TemplateSyntaxError: Invalid block tag on line 3: 'get_user_posts'. Did you forget to register or load this tag?
2021-11-12 22:27:00,807 django.request ERROR    Internal Server Error: /profile/a
Traceback (most recent call last):
  File "C:\Users\tarlo\AppData\Local\Programs\Python\Python39\lib\site-packages\django\template\base.py", line 470, in parse
    compile_func = self.tags[command]
KeyError: 'get_user_posts'

During handling of the above exception, another exception occurred:

Traceback (most recent call last):
  File "C:\Users\tarlo\AppData\Local\Programs\Python\Python39\lib\site-packages\django\core\handlers\exception.py", line 47, in inner
    response = get_response(request)
  File "C:\Users\tarlo\AppData\Local\Programs\Python\Python39\lib\site-packages\django\core\handlers\base.py", line 181, in _get_response
    response = wrapped_callback(request, *callback_args, **callback_kwargs)
  File "C:\Users\tarlo\AppData\Local\Programs\Python\Python39\lib\site-packages\django\views\generic\base.py", line 70, in view
    return self.dispatch(request, *args, **kwargs)
  File "C:\Users\tarlo\AppData\Local\Programs\Python\Python39\lib\site-packages\django\views\generic\base.py", line 98, in dispatch
    return handler(request, *args, **kwargs)
  File "C:\Users\tarlo\Desktop\Code\Python\instamiligram\users\views.py", line 108, in get
    return render(request, "users/profile.html", {"user": User.objects.filter(username=username).first()})
  File "C:\Users\tarlo\AppData\Local\Programs\Python\Python39\lib\site-packages\django\shortcuts.py", line 19, in render
    content = loader.render_to_string(template_name, context, request, using=using)
  File "C:\Users\tarlo\AppData\Local\Programs\Python\Python39\lib\site-packages\django\template\loader.py", line 61, in render_to_string
    template = get_template(template_name, using=using)
  File "C:\Users\tarlo\AppData\Local\Programs\Python\Python39\lib\site-packages\django\template\loader.py", line 15, in get_template
    return engine.get_template(template_name)
  File "C:\Users\tarlo\AppData\Local\Programs\Python\Python39\lib\site-packages\django\template\backends\django.py", line 34, in get_template
    return Template(self.engine.get_template(template_name), self)
  File "C:\Users\tarlo\AppData\Local\Programs\Python\Python39\lib\site-packages\django\template\engine.py", line 143, in get_template
    template, origin = self.find_template(template_name)
  File "C:\Users\tarlo\AppData\Local\Programs\Python\Python39\lib\site-packages\django\template\engine.py", line 125, in find_template
    template = loader.get_template(name, skip=skip)
  File "C:\Users\tarlo\AppData\Local\Programs\Python\Python39\lib\site-packages\django\template\loaders\base.py", line 29, in get_template
    return Template(
  File "C:\Users\tarlo\AppData\Local\Programs\Python\Python39\lib\site-packages\django\template\base.py", line 155, in __init__
    self.nodelist = self.compile_nodelist()
  File "C:\Users\tarlo\AppData\Local\Programs\Python\Python39\lib\site-packages\django\template\base.py", line 193, in compile_nodelist
    return parser.parse()
  File "C:\Users\tarlo\AppData\Local\Programs\Python\Python39\lib\site-packages\django\template\base.py", line 478, in parse
    raise self.error(token, e)
  File "C:\Users\tarlo\AppData\Local\Programs\Python\Python39\lib\site-packages\django\template\base.py", line 476, in parse
    compiled_result = compile_func(self, token)
  File "C:\Users\tarlo\AppData\Local\Programs\Python\Python39\lib\site-packages\django\template\loader_tags.py", line 278, in do_extends
    nodelist = parser.parse()
  File "C:\Users\tarlo\AppData\Local\Programs\Python\Python39\lib\site-packages\django\template\base.py", line 472, in parse
    self.invalid_block_tag(token, command, parse_until)
  File "C:\Users\tarlo\AppData\Local\Programs\Python\Python39\lib\site-packages\django\template\base.py", line 531, in invalid_block_tag
    raise self.error(
django.template.exceptions.TemplateSyntaxError: Invalid block tag on line 5: 'get_user_posts'. Did you forget to register or load this tag?
2021-11-12 22:27:35,716 django.request ERROR    Internal Server Error: /profile/a
Traceback (most recent call last):
  File "C:\Users\tarlo\AppData\Local\Programs\Python\Python39\lib\site-packages\django\template\base.py", line 470, in parse
    compile_func = self.tags[command]
KeyError: 'get_user_posts'

During handling of the above exception, another exception occurred:

Traceback (most recent call last):
  File "C:\Users\tarlo\AppData\Local\Programs\Python\Python39\lib\site-packages\django\core\handlers\exception.py", line 47, in inner
    response = get_response(request)
  File "C:\Users\tarlo\AppData\Local\Programs\Python\Python39\lib\site-packages\django\core\handlers\base.py", line 181, in _get_response
    response = wrapped_callback(request, *callback_args, **callback_kwargs)
  File "C:\Users\tarlo\AppData\Local\Programs\Python\Python39\lib\site-packages\django\views\generic\base.py", line 70, in view
    return self.dispatch(request, *args, **kwargs)
  File "C:\Users\tarlo\AppData\Local\Programs\Python\Python39\lib\site-packages\django\views\generic\base.py", line 98, in dispatch
    return handler(request, *args, **kwargs)
  File "C:\Users\tarlo\Desktop\Code\Python\instamiligram\users\views.py", line 108, in get
    return render(request, "users/profile.html", {"user": User.objects.filter(username=username).first()})
  File "C:\Users\tarlo\AppData\Local\Programs\Python\Python39\lib\site-packages\django\shortcuts.py", line 19, in render
    content = loader.render_to_string(template_name, context, request, using=using)
  File "C:\Users\tarlo\AppData\Local\Programs\Python\Python39\lib\site-packages\django\template\loader.py", line 61, in render_to_string
    template = get_template(template_name, using=using)
  File "C:\Users\tarlo\AppData\Local\Programs\Python\Python39\lib\site-packages\django\template\loader.py", line 15, in get_template
    return engine.get_template(template_name)
  File "C:\Users\tarlo\AppData\Local\Programs\Python\Python39\lib\site-packages\django\template\backends\django.py", line 34, in get_template
    return Template(self.engine.get_template(template_name), self)
  File "C:\Users\tarlo\AppData\Local\Programs\Python\Python39\lib\site-packages\django\template\engine.py", line 143, in get_template
    template, origin = self.find_template(template_name)
  File "C:\Users\tarlo\AppData\Local\Programs\Python\Python39\lib\site-packages\django\template\engine.py", line 125, in find_template
    template = loader.get_template(name, skip=skip)
  File "C:\Users\tarlo\AppData\Local\Programs\Python\Python39\lib\site-packages\django\template\loaders\base.py", line 29, in get_template
    return Template(
  File "C:\Users\tarlo\AppData\Local\Programs\Python\Python39\lib\site-packages\django\template\base.py", line 155, in __init__
    self.nodelist = self.compile_nodelist()
  File "C:\Users\tarlo\AppData\Local\Programs\Python\Python39\lib\site-packages\django\template\base.py", line 193, in compile_nodelist
    return parser.parse()
  File "C:\Users\tarlo\AppData\Local\Programs\Python\Python39\lib\site-packages\django\template\base.py", line 478, in parse
    raise self.error(token, e)
  File "C:\Users\tarlo\AppData\Local\Programs\Python\Python39\lib\site-packages\django\template\base.py", line 476, in parse
    compiled_result = compile_func(self, token)
  File "C:\Users\tarlo\AppData\Local\Programs\Python\Python39\lib\site-packages\django\template\loader_tags.py", line 278, in do_extends
    nodelist = parser.parse()
  File "C:\Users\tarlo\AppData\Local\Programs\Python\Python39\lib\site-packages\django\template\base.py", line 472, in parse
    self.invalid_block_tag(token, command, parse_until)
  File "C:\Users\tarlo\AppData\Local\Programs\Python\Python39\lib\site-packages\django\template\base.py", line 531, in invalid_block_tag
    raise self.error(
django.template.exceptions.TemplateSyntaxError: Invalid block tag on line 7: 'get_user_posts'. Did you forget to register or load this tag?
2021-11-12 22:39:12,924 django.request ERROR    Internal Server Error: /chat/koji
Traceback (most recent call last):
  File "C:\Users\tarlo\AppData\Local\Programs\Python\Python39\lib\site-packages\django\core\handlers\exception.py", line 47, in inner
    response = get_response(request)
  File "C:\Users\tarlo\AppData\Local\Programs\Python\Python39\lib\site-packages\django\core\handlers\base.py", line 181, in _get_response
    response = wrapped_callback(request, *callback_args, **callback_kwargs)
  File "C:\Users\tarlo\AppData\Local\Programs\Python\Python39\lib\site-packages\django\views\generic\base.py", line 70, in view
    return self.dispatch(request, *args, **kwargs)
  File "C:\Users\tarlo\AppData\Local\Programs\Python\Python39\lib\site-packages\django\views\generic\base.py", line 98, in dispatch
    return handler(request, *args, **kwargs)
  File "C:\Users\tarlo\Desktop\Code\Python\instamiligram\chat\views.py", line 40, in get
    return render(request, 'chat/chat-dialog.html', context={
  File "C:\Users\tarlo\AppData\Local\Programs\Python\Python39\lib\site-packages\django\shortcuts.py", line 19, in render
    content = loader.render_to_string(template_name, context, request, using=using)
  File "C:\Users\tarlo\AppData\Local\Programs\Python\Python39\lib\site-packages\django\template\loader.py", line 62, in render_to_string
    return template.render(context, request)
  File "C:\Users\tarlo\AppData\Local\Programs\Python\Python39\lib\site-packages\django\template\backends\django.py", line 61, in render
    return self.template.render(context)
  File "C:\Users\tarlo\AppData\Local\Programs\Python\Python39\lib\site-packages\django\template\base.py", line 170, in render
    return self._render(context)
  File "C:\Users\tarlo\AppData\Local\Programs\Python\Python39\lib\site-packages\django\template\base.py", line 162, in _render
    return self.nodelist.render(context)
  File "C:\Users\tarlo\AppData\Local\Programs\Python\Python39\lib\site-packages\django\template\base.py", line 938, in render
    bit = node.render_annotated(context)
  File "C:\Users\tarlo\AppData\Local\Programs\Python\Python39\lib\site-packages\django\template\base.py", line 905, in render_annotated
    return self.render(context)
  File "C:\Users\tarlo\AppData\Local\Programs\Python\Python39\lib\site-packages\django\template\loader_tags.py", line 150, in render
    return compiled_parent._render(context)
  File "C:\Users\tarlo\AppData\Local\Programs\Python\Python39\lib\site-packages\django\template\base.py", line 162, in _render
    return self.nodelist.render(context)
  File "C:\Users\tarlo\AppData\Local\Programs\Python\Python39\lib\site-packages\django\template\base.py", line 938, in render
    bit = node.render_annotated(context)
  File "C:\Users\tarlo\AppData\Local\Programs\Python\Python39\lib\site-packages\django\template\base.py", line 905, in render_annotated
    return self.render(context)
  File "C:\Users\tarlo\AppData\Local\Programs\Python\Python39\lib\site-packages\django\template\loader_tags.py", line 62, in render
    result = block.nodelist.render(context)
  File "C:\Users\tarlo\AppData\Local\Programs\Python\Python39\lib\site-packages\django\template\base.py", line 938, in render
    bit = node.render_annotated(context)
  File "C:\Users\tarlo\AppData\Local\Programs\Python\Python39\lib\site-packages\django\template\base.py", line 905, in render_annotated
    return self.render(context)
  File "C:\Users\tarlo\AppData\Local\Programs\Python\Python39\lib\site-packages\django\template\defaulttags.py", line 446, in render
    url = reverse(view_name, args=args, kwargs=kwargs, current_app=current_app)
  File "C:\Users\tarlo\AppData\Local\Programs\Python\Python39\lib\site-packages\django\urls\base.py", line 86, in reverse
    return resolver._reverse_with_prefix(view, prefix, *args, **kwargs)
  File "C:\Users\tarlo\AppData\Local\Programs\Python\Python39\lib\site-packages\django\urls\resolvers.py", line 694, in _reverse_with_prefix
    raise NoReverseMatch(msg)
django.urls.exceptions.NoReverseMatch: Reverse for 'send_message' not found. 'send_message' is not a valid view function or pattern name.
2021-11-12 22:41:15,886 django.request WARNING  Method Not Allowed (POST): /chat/sendmsg
2021-11-12 22:41:15,887 django.request WARNING  Method Not Allowed: /chat/sendmsg
2021-11-12 22:44:28,183 django.request WARNING  Method Not Allowed (POST): /chat/sendmsg
2021-11-12 22:44:28,184 django.request WARNING  Method Not Allowed: /chat/sendmsg
2021-11-12 22:47:05,192 django.request WARNING  Method Not Allowed (POST): /chat/sendmsg
2021-11-12 22:47:05,192 django.request WARNING  Method Not Allowed: /chat/sendmsg
2021-11-12 22:47:28,475 django.request ERROR    Internal Server Error: /chat/sendmsg
Traceback (most recent call last):
  File "C:\Users\tarlo\AppData\Local\Programs\Python\Python39\lib\site-packages\django\core\handlers\exception.py", line 47, in inner
    response = get_response(request)
  File "C:\Users\tarlo\AppData\Local\Programs\Python\Python39\lib\site-packages\django\core\handlers\base.py", line 181, in _get_response
    response = wrapped_callback(request, *callback_args, **callback_kwargs)
  File "C:\Users\tarlo\AppData\Local\Programs\Python\Python39\lib\site-packages\django\views\generic\base.py", line 70, in view
    return self.dispatch(request, *args, **kwargs)
  File "C:\Users\tarlo\AppData\Local\Programs\Python\Python39\lib\site-packages\django\contrib\auth\mixins.py", line 71, in dispatch
    return super().dispatch(request, *args, **kwargs)
  File "C:\Users\tarlo\AppData\Local\Programs\Python\Python39\lib\site-packages\django\views\generic\base.py", line 98, in dispatch
    return handler(request, *args, **kwargs)
TypeError: post() got an unexpected keyword argument 'username'
2021-11-12 22:55:34,120 django.request WARNING  Method Not Allowed (POST): /chat/koji
2021-11-12 22:55:34,120 django.request WARNING  Method Not Allowed: /chat/koji
2021-11-12 22:57:58,476 django.request ERROR    Internal Server Error: /chat/koji
Traceback (most recent call last):
  File "C:\Users\tarlo\AppData\Local\Programs\Python\Python39\lib\site-packages\django\core\handlers\exception.py", line 47, in inner
    response = get_response(request)
  File "C:\Users\tarlo\AppData\Local\Programs\Python\Python39\lib\site-packages\django\core\handlers\base.py", line 181, in _get_response
    response = wrapped_callback(request, *callback_args, **callback_kwargs)
  File "C:\Users\tarlo\AppData\Local\Programs\Python\Python39\lib\site-packages\django\views\generic\base.py", line 70, in view
    return self.dispatch(request, *args, **kwargs)
  File "C:\Users\tarlo\AppData\Local\Programs\Python\Python39\lib\site-packages\django\contrib\auth\mixins.py", line 71, in dispatch
    return super().dispatch(request, *args, **kwargs)
  File "C:\Users\tarlo\AppData\Local\Programs\Python\Python39\lib\site-packages\django\views\generic\base.py", line 98, in dispatch
    return handler(request, *args, **kwargs)
  File "C:\Users\tarlo\Desktop\Code\Python\instamiligram\chat\views.py", line 41, in get
    return render(request, 'chat/chat-dialog.html', context={
  File "C:\Users\tarlo\AppData\Local\Programs\Python\Python39\lib\site-packages\django\shortcuts.py", line 19, in render
    content = loader.render_to_string(template_name, context, request, using=using)
  File "C:\Users\tarlo\AppData\Local\Programs\Python\Python39\lib\site-packages\django\template\loader.py", line 62, in render_to_string
    return template.render(context, request)
  File "C:\Users\tarlo\AppData\Local\Programs\Python\Python39\lib\site-packages\django\template\backends\django.py", line 61, in render
    return self.template.render(context)
  File "C:\Users\tarlo\AppData\Local\Programs\Python\Python39\lib\site-packages\django\template\base.py", line 170, in render
    return self._render(context)
  File "C:\Users\tarlo\AppData\Local\Programs\Python\Python39\lib\site-packages\django\template\base.py", line 162, in _render
    return self.nodelist.render(context)
  File "C:\Users\tarlo\AppData\Local\Programs\Python\Python39\lib\site-packages\django\template\base.py", line 938, in render
    bit = node.render_annotated(context)
  File "C:\Users\tarlo\AppData\Local\Programs\Python\Python39\lib\site-packages\django\template\base.py", line 905, in render_annotated
    return self.render(context)
  File "C:\Users\tarlo\AppData\Local\Programs\Python\Python39\lib\site-packages\django\template\loader_tags.py", line 150, in render
    return compiled_parent._render(context)
  File "C:\Users\tarlo\AppData\Local\Programs\Python\Python39\lib\site-packages\django\template\base.py", line 162, in _render
    return self.nodelist.render(context)
  File "C:\Users\tarlo\AppData\Local\Programs\Python\Python39\lib\site-packages\django\template\base.py", line 938, in render
    bit = node.render_annotated(context)
  File "C:\Users\tarlo\AppData\Local\Programs\Python\Python39\lib\site-packages\django\template\base.py", line 905, in render_annotated
    return self.render(context)
  File "C:\Users\tarlo\AppData\Local\Programs\Python\Python39\lib\site-packages\django\template\loader_tags.py", line 62, in render
    result = block.nodelist.render(context)
  File "C:\Users\tarlo\AppData\Local\Programs\Python\Python39\lib\site-packages\django\template\base.py", line 938, in render
    bit = node.render_annotated(context)
  File "C:\Users\tarlo\AppData\Local\Programs\Python\Python39\lib\site-packages\django\template\base.py", line 905, in render_annotated
    return self.render(context)
  File "C:\Users\tarlo\AppData\Local\Programs\Python\Python39\lib\site-packages\django\template\defaulttags.py", line 446, in render
    url = reverse(view_name, args=args, kwargs=kwargs, current_app=current_app)
  File "C:\Users\tarlo\AppData\Local\Programs\Python\Python39\lib\site-packages\django\urls\base.py", line 86, in reverse
    return resolver._reverse_with_prefix(view, prefix, *args, **kwargs)
  File "C:\Users\tarlo\AppData\Local\Programs\Python\Python39\lib\site-packages\django\urls\resolvers.py", line 694, in _reverse_with_prefix
    raise NoReverseMatch(msg)
django.urls.exceptions.NoReverseMatch: Reverse for 'send_message' not found. 'send_message' is not a valid view function or pattern name.
2021-11-12 22:58:19,145 django.request ERROR    Internal Server Error: /chat/koji
Traceback (most recent call last):
  File "C:\Users\tarlo\AppData\Local\Programs\Python\Python39\lib\site-packages\django\core\handlers\exception.py", line 47, in inner
    response = get_response(request)
  File "C:\Users\tarlo\AppData\Local\Programs\Python\Python39\lib\site-packages\django\core\handlers\base.py", line 181, in _get_response
    response = wrapped_callback(request, *callback_args, **callback_kwargs)
  File "C:\Users\tarlo\AppData\Local\Programs\Python\Python39\lib\site-packages\django\views\generic\base.py", line 70, in view
    return self.dispatch(request, *args, **kwargs)
  File "C:\Users\tarlo\AppData\Local\Programs\Python\Python39\lib\site-packages\django\contrib\auth\mixins.py", line 71, in dispatch
    return super().dispatch(request, *args, **kwargs)
  File "C:\Users\tarlo\AppData\Local\Programs\Python\Python39\lib\site-packages\django\views\generic\base.py", line 98, in dispatch
    return handler(request, *args, **kwargs)
  File "C:\Users\tarlo\Desktop\Code\Python\instamiligram\chat\views.py", line 49, in post
    target = User.objects.fiter(username=username).first()
AttributeError: 'UserManager' object has no attribute 'fiter'
2021-11-12 22:58:27,610 django.request ERROR    Internal Server Error: /chat/koji
Traceback (most recent call last):
  File "C:\Users\tarlo\AppData\Local\Programs\Python\Python39\lib\site-packages\django\core\handlers\exception.py", line 47, in inner
    response = get_response(request)
  File "C:\Users\tarlo\AppData\Local\Programs\Python\Python39\lib\site-packages\django\core\handlers\base.py", line 181, in _get_response
    response = wrapped_callback(request, *callback_args, **callback_kwargs)
  File "C:\Users\tarlo\AppData\Local\Programs\Python\Python39\lib\site-packages\django\views\generic\base.py", line 70, in view
    return self.dispatch(request, *args, **kwargs)
  File "C:\Users\tarlo\AppData\Local\Programs\Python\Python39\lib\site-packages\django\contrib\auth\mixins.py", line 71, in dispatch
    return super().dispatch(request, *args, **kwargs)
  File "C:\Users\tarlo\AppData\Local\Programs\Python\Python39\lib\site-packages\django\views\generic\base.py", line 98, in dispatch
    return handler(request, *args, **kwargs)
  File "C:\Users\tarlo\Desktop\Code\Python\instamiligram\chat\views.py", line 53, in post
    return self.get()
TypeError: get() missing 2 required positional arguments: 'request' and 'username'
2021-11-12 23:05:51,284 django.request ERROR    Internal Server Error: /chats/
Traceback (most recent call last):
  File "C:\Users\tarlo\AppData\Local\Programs\Python\Python39\lib\site-packages\django\core\handlers\exception.py", line 47, in inner
    response = get_response(request)
  File "C:\Users\tarlo\AppData\Local\Programs\Python\Python39\lib\site-packages\django\core\handlers\base.py", line 181, in _get_response
    response = wrapped_callback(request, *callback_args, **callback_kwargs)
  File "C:\Users\tarlo\AppData\Local\Programs\Python\Python39\lib\site-packages\django\views\generic\base.py", line 70, in view
    return self.dispatch(request, *args, **kwargs)
  File "C:\Users\tarlo\AppData\Local\Programs\Python\Python39\lib\site-packages\django\contrib\auth\mixins.py", line 71, in dispatch
    return super().dispatch(request, *args, **kwargs)
  File "C:\Users\tarlo\AppData\Local\Programs\Python\Python39\lib\site-packages\django\views\generic\base.py", line 98, in dispatch
    return handler(request, *args, **kwargs)
  File "C:\Users\tarlo\Desktop\Code\Python\instamiligram\chat\views.py", line 27, in get
    m1 = Message.objects.filter(recipient=_messages[i].recipient,sender=_messages[i].sender).first()
TypeError: list indices must be integers or slices, not Message
